Workbook

Sheet Fases
A1: Esqueleto estándar · P2R · Plan to Release
A2: Transcrito de la aplicación el 29/10/2026. Repositorio: sin repositorio · 8 palancas lo usan · 0 con uno propio. Variantes de P2R: 0 (todas las celdas usan el esqueleto estándar).
A4: Orden | B4: Fase | C4: Tramo | D4: Descripción (de → a) | E4: Opcional | F4: Áreas de negocio | G4: Actividades | H4: Hallazgos del catálogo | I4: Palancas del catálogo
A5: 1 | B5: Demanda y previsión (Forecast to Plan) | C5: Forecast to Plan | D5: De Histórico y Señal de Mercado --> Demanda Consensuada | E5: — | F5: todas | G5: 7 | H5: =COUNTIF(Hallazgos!$C$5:$C$15,B5) -> 1 | I5: =COUNTIF(Palancas!$F$5:$F$12,B5) -> 1
A6: 3 | B6: S&OP y Plan Maestro (Forecast to Plan) | C6: Forecast to Plan | D6: De Demanda Global --> Equilibrio Demanda, Capacidad y Recursos | E6: — | F6: todas | G6: 7 | H6: =COUNTIF(Hallazgos!$C$5:$C$15,B6) -> 3 | I6: =COUNTIF(Palancas!$F$5:$F$12,B6) -> 3
A7: 5 | B7: Necesidades de Fabricación y MRP | C7: Plan to Produce | D7: De Plan Maestro --> Órdenes Previsionales de Fabricación y Solicitudes de Compra | E7: — | F7: todas | G7: 8 | H7: =COUNTIF(Hallazgos!$C$5:$C$15,B7) -> 2 | I7: =COUNTIF(Palancas!$F$5:$F$12,B7) -> 1
A8: 6 | B8: Programación | C8: Plan to Produce | D8: De Orden Previsional --> Secuencia por Línea y Turno | E8: — | F8: todas | G8: 6 | H8: =COUNTIF(Hallazgos!$C$5:$C$15,B8) -> 2 | I8: =COUNTIF(Palancas!$F$5:$F$12,B8) -> 1
A9: 7 | B9: Liberación | C9: Plan to Produce | D9: De Orden Programada --> Orden Liberada Ejecutable | E9: — | F9: todas | G9: 4 | H9: =COUNTIF(Hallazgos!$C$5:$C$15,B9) -> 1 | I9: =COUNTIF(Palancas!$F$5:$F$12,B9) -> 1
A10: 8 | B10: Seguimiento y Control | C10: Plan to Produce | D10: De Plan Ejecutado --> Desviaciones Explicadas con Acción | E10: — | F10: todas | G10: 9 | H10: =COUNTIF(Hallazgos!$C$5:$C$15,B10) -> 2 | I10: =COUNTIF(Palancas!$F$5:$F$12,B10) -> 1
A11: Total | G11: =SUM(G5:G10) -> 41 | H11: =SUM(H5:H10) -> 11 | I11: =SUM(I5:I10) -> 8

Sheet Personas
A1: Personas por empresa
A2: Transcrito de la aplicación el 29/10/2026 (área de negocio Packaging, 14 personas). Coste anual estimado. «Σ dedicación» es el dato de la aplicación; «Dedicación detallada» suma la hoja Dedicación.
A4: Persona | B4: ID | C4: Email | D4: Categoría | E4: Roles | F4: Censo en | G4: Área de negocio | H4: Jornada h/año | I4: Coste anual (k€) | J4: Σ Dedicación | K4: Coste imputado (k€) | L4: Dedicación detallada | M4: Sin detallar | N4: Licencias
A5: Victoriano Pérez Carrasco | B5: ID-20 | C5: vperez@clgrupoindustrial.com | D5: Técnico especialista | E5: Planificación · Planificador de la producción | F5: Ondupet | G5: Packaging | H5: 1720 | I5: 60.2 | J5: 1 | K5: =I5*J5 -> 60.2 | L5: =SUMIF(Dedicación!$A$5:$A$12,A5,Dedicación!$E$5:$E$12) -> 1 | M5: =J5-L5 -> 0 | N5: sin licencias
A6: Bárbara Ayuste Tejera | B6: ID-22 | C6: bayuste@ondupet.es | D6: Administrativo | E6: Compras · Category Manager; Compras · Tramitadores de compras | F6: Ondupet | G6: Packaging | H6: 1720 | I6: 37.8 | J6: 0.25 | K6: =I6*J6 -> 9.45 | L6: =SUMIF(Dedicación!$A$5:$A$12,A6,Dedicación!$E$5:$E$12) -> 0.25 | M6: =J6-L6 -> 0 | N6: SAP ECC · usuario
A7: Manuel Jesús Trinidad Montero | B7: ID-24 | C7: mjtrinidad@ondupet.es | D7: Responsable / mando intermedio | E7: Comercial · Comercial con potestad | F7: Ondupet | G7: Packaging | H7: 1720 | I7: 82.6 | J7: 0.15 | K7: =I7*J7 -> 12.39 | L7: =SUMIF(Dedicación!$A$5:$A$12,A7,Dedicación!$E$5:$E$12) -> 0.15 | M7: =J7-L7 -> 0 | N7: sin licencias
A8: Monica Gordillo Guerrero | B8: ID-21 | C8: mgordillo@ondupet.es | D8: Administrativo | E8: Comercial · Comercial con potestad; Comercial · Administración de ventas | F8: Ondupet | G8: Packaging | H8: 1720 | I8: 37.8 | J8: 0.2 | K8: =I8*J8 -> 7.56 | L8: =SUMIF(Dedicación!$A$5:$A$12,A8,Dedicación!$E$5:$E$12) -> 0.2 | M8: =J8-L8 -> 0 | N8: sin licencias
A9: Antonio Nogales Carrión | B9: ID-23 | C9: anogales@ondupet.es | D9: Responsable / mando intermedio | E9: Compras · Category Manager; Compras · Tramitadores de compras | F9: Ondupet | G9: Packaging | H9: 1720 | I9: 82.6 | J9: 0 | K9: =I9*J9 -> 0 | L9: =SUMIF(Dedicación!$A$5:$A$12,A9,Dedicación!$E$5:$E$12) -> 0 | M9: =J9-L9 -> 0
A10: Miguel Ángel Rosado Martínez | B10: sin ID | C10: planificacion@ondupack.com | D10: Técnico especialista | E10: Planificación · Planificador de la producción; Logística · Responsable Expediciones | F10: Ondupack | G10: Cartón | H10: 1720 | I10: 60.2 | J10: 0 | K10: =I10*J10 -> 0 | L10: =SUMIF(Dedicación!$A$5:$A$12,A10,Dedicación!$E$5:$E$12) -> 0 | M10: =J10-L10 -> 0
A11: Tomás Buenavida Santiago | B11: sin ID | C11: tbuenavida@ondupack.com | D11: Administrativo | E11: Planificación · Planificador de la producción | F11: Ondupack | G11: Cartón | H11: 1720 | I11: 37.8 | J11: 0 | K11: =I11*J11 -> 0 | L11: =SUMIF(Dedicación!$A$5:$A$12,A11,Dedicación!$E$5:$E$12) -> 0 | M11: =J11-L11 -> 0
A12: Maria Teresa Espinosa Paredes | B12: sin ID | C12: tere_att@ondupack.com | D12: Técnico especialista | E12: Comercial | F12: Ondupack | G12: Cartón | H12: 1720 | I12: 60.2 | J12: 0.1 | K12: =I12*J12 -> 6.02 | L12: =SUMIF(Dedicación!$A$5:$A$12,A12,Dedicación!$E$5:$E$12) -> 0 | M12: =J12-L12 -> 0.1
A13: José María Baquero Jaen | B13: sin ID | C13: jbaquero@ondupack.com | D13: Responsable / mando intermedio | E13: Producción · Responsable Producción | F13: Ondupack | G13: Cartón | H13: 1720 | I13: 82.6 | J13: 0 | K13: =I13*J13 -> 0 | L13: =SUMIF(Dedicación!$A$5:$A$12,A13,Dedicación!$E$5:$E$12) -> 0 | M13: =J13-L13 -> 0
A14: Angélica Lemus Fernández | B14: sin ID | C14: alemus@ondupack.com | D14: Responsable / mando intermedio | E14: Compras · Category Manager | F14: Ondupack | G14: Cartón | H14: 1720 | I14: 82.6 | J14: 0 | K14: =I14*J14 -> 0 | L14: =SUMIF(Dedicación!$A$5:$A$12,A14,Dedicación!$E$5:$E$12) -> 0 | M14: =J14-L14 -> 0
A15: Karim Karach Boujtat | B15: sin ID | C15: kkarach@ondupack.com | D15: Responsable / mando intermedio | E15: Producción · Responsable Producción | F15: Navalmoral | G15: Cartón | H15: 1720 | I15: 82.6 | J15: 0 | K15: =I15*J15 -> 0 | L15: =SUMIF(Dedicación!$A$5:$A$12,A15,Dedicación!$E$5:$E$12) -> 0 | M15: =J15-L15 -> 0
A16: Joan Carles Girones Campaña | B16: sin ID | C16: jc.girones@matiasgomatomas.com | D16: Técnico especialista | E16: Planificación · Planificador de la producción | F16: MGT | G16: Papel | H16: 1720 | I16: 60.2 | J16: 0 | K16: =I16*J16 -> 0 | L16: =SUMIF(Dedicación!$A$5:$A$12,A16,Dedicación!$E$5:$E$12) -> 0 | M16: =J16-L16 -> 0
A17: Marta Boyo Martinez | B17: sin ID | C17: m.boyo@matiasgomatomas.com | D17: Técnico especialista | E17: Compras · Category Manager | F17: MGT | G17: Papel | H17: 1720 | I17: 60.2 | J17: 0 | K17: =I17*J17 -> 0 | L17: =SUMIF(Dedicación!$A$5:$A$12,A17,Dedicación!$E$5:$E$12) -> 0 | M17: =J17-L17 -> 0
A18: Albert Fontanet Lopez | B18: sin ID | C18: a.fontanet@matiasgomatomas.com | D18: Responsable / mando intermedio | E18: Comercial | F18: MGT | G18: Papel | H18: 1720 | I18: 82.6 | J18: 0 | K18: =I18*J18 -> 0 | L18: =SUMIF(Dedicación!$A$5:$A$12,A18,Dedicación!$E$5:$E$12) -> 0 | M18: =J18-L18 -> 0
A19: Σ 14 personas | H19: =SUM(H5:H18) -> 24080 | I19: =SUM(I5:I18) -> 910 | K19: =SUM(K5:K18) -> 95.62

Sheet Dedicación
A1: Dedicación por celda y fase
A2: Una fila por persona, celda (proceso × empresa) y fase. Por ahora solo está el detalle de P2R × Ondupet.
A4: Persona | B4: Censo en | C4: Celda | D4: Fase | E4: % dedicación | F4: Coste imputado (k€)
A5: Bárbara Ayuste Tejera | B5: =INDEX(Personas!$F$5:$F$18,MATCH(A5,Personas!$A$5:$A$18,0)) -> Ondupet | C5: P2R × Ondupet | D5: Necesidades de Fabricación y MRP | E5: 0.25 | F5: =E5*INDEX(Personas!$I$5:$I$18,MATCH(A5,Personas!$A$5:$A$18,0)) -> 9.45
A6: Manuel Jesús Trinidad Montero | B6: =INDEX(Personas!$F$5:$F$18,MATCH(A6,Personas!$A$5:$A$18,0)) -> Ondupet | C6: P2R × Ondupet | D6: S&OP y Plan Maestro (Forecast to Plan) | E6: 0.15 | F6: =E6*INDEX(Personas!$I$5:$I$18,MATCH(A6,Personas!$A$5:$A$18,0)) -> 12.39
A7: Monica Gordillo Guerrero | B7: =INDEX(Personas!$F$5:$F$18,MATCH(A7,Personas!$A$5:$A$18,0)) -> Ondupet | C7: P2R × Ondupet | D7: S&OP y Plan Maestro (Forecast to Plan) | E7: 0.2 | F7: =E7*INDEX(Personas!$I$5:$I$18,MATCH(A7,Personas!$A$5:$A$18,0)) -> 7.56
A8: Victoriano Pérez Carrasco | B8: =INDEX(Personas!$F$5:$F$18,MATCH(A8,Personas!$A$5:$A$18,0)) -> Ondupet | C8: P2R × Ondupet | D8: Necesidades de Fabricación y MRP | E8: 0.3 | F8: =E8*INDEX(Personas!$I$5:$I$18,MATCH(A8,Personas!$A$5:$A$18,0)) -> 18.06
A9: Victoriano Pérez Carrasco | B9: =INDEX(Personas!$F$5:$F$18,MATCH(A9,Personas!$A$5:$A$18,0)) -> Ondupet | C9: P2R × Ondupet | D9: Liberación | E9: 0.25 | F9: =E9*INDEX(Personas!$I$5:$I$18,MATCH(A9,Personas!$A$5:$A$18,0)) -> 15.05
A10: Victoriano Pérez Carrasco | B10: =INDEX(Personas!$F$5:$F$18,MATCH(A10,Personas!$A$5:$A$18,0)) -> Ondupet | C10: P2R × Ondupet | D10: Programación | E10: 0.25 | F10: =E10*INDEX(Personas!$I$5:$I$18,MATCH(A10,Personas!$A$5:$A$18,0)) -> 15.05
A11: Victoriano Pérez Carrasco | B11: =INDEX(Personas!$F$5:$F$18,MATCH(A11,Personas!$A$5:$A$18,0)) -> Ondupet | C11: P2R × Ondupet | D11: Seguimiento y Control | E11: 0.15 | F11: =E11*INDEX(Personas!$I$5:$I$18,MATCH(A11,Personas!$A$5:$A$18,0)) -> 9.03
A12: Victoriano Pérez Carrasco | B12: =INDEX(Personas!$F$5:$F$18,MATCH(A12,Personas!$A$5:$A$18,0)) -> Ondupet | C12: P2R × Ondupet | D12: Demanda y previsión (Forecast to Plan) | E12: 0.05 | F12: =E12*INDEX(Personas!$I$5:$I$18,MATCH(A12,Personas!$A$5:$A$18,0)) -> 3.01
A15: Resumen por celda | B15: Personas | C15: Coste imputado (k€)
A16: P2R × Ondupet | B16: =SUMPRODUCT((Dedicación!$C$5:$C$12=A16)/COUNTIFS(Dedicación!$A$5:$A$12,Dedicación!$A$5:$A$12,Dedicación!$C$5:$C$12,Dedicación!$C$5:$C$12)) -> 4 | C16: =SUMIF(Dedicación!$C$5:$C$12,A16,Dedicación!$F$5:$F$12) -> 89.6
A17: P2R × Ondupack | B17: =SUMPRODUCT((Dedicación!$C$5:$C$12=A17)/COUNTIFS(Dedicación!$A$5:$A$12,Dedicación!$A$5:$A$12,Dedicación!$C$5:$C$12,Dedicación!$C$5:$C$12)) -> 0 | C17: =SUMIF(Dedicación!$C$5:$C$12,A17,Dedicación!$F$5:$F$12) -> 0
A18: P2R × MGT | B18: =SUMPRODUCT((Dedicación!$C$5:$C$12=A18)/COUNTIFS(Dedicación!$A$5:$A$12,Dedicación!$A$5:$A$12,Dedicación!$C$5:$C$12,Dedicación!$C$5:$C$12)) -> 0 | C18: =SUMIF(Dedicación!$C$5:$C$12,A18,Dedicación!$F$5:$F$12) -> 0

Sheet Hallazgos
A1: Catálogo de tipos de hallazgo · P2R
A2: Transcrito de la aplicación el 29/10/2026 (11 tipos). Descripción, métrica, KPI y fórmula del maestro; en la fórmula, valor y obj son los tokens de la aplicación y las constantes son de ejemplo. «Empresas» se calcula con las columnas de cada empresa.
A4: ID | B4: Nombre | C4: Fase | D4: Descripción | E4: Familia | F4: Naturaleza | G4: Métrica (volumen expuesto) | H4: KPI sugerido | I4: Fórmula sugerida (€/año) | J4: Se cura con | K4: Ondupet | L4: Ondupack | M4: MGT | N4: Empresas | O4: Caza inversa
A5: HT-P2R-01 | B5: Demanda sin previsión fiable | C5: Demanda y previsión (Forecast to Plan) | D5: No hay previsión, o la que hay no se cierra, no se consensúa ni se mide: el plan trabaja con una demanda que cambia o que no se conoce, y la demanda perdida no se registra. | E5: Ineficiencia | F5: Circulante | G5: € de demanda mensual planificada sin previsión cerrada y consensuada | H5: Precisión de la previsión (1 − WMAPE, %) ↑ | I5: (obj-valor)/100*2000000*0.08 | J5: P2R-01 | K5: ✓ | L5: ✓ | M5: ✓ | N5: =COUNTIF(K5:M5,"✓") -> 3 | O5: —
A6: HT-P2R-03 | B6: Demanda y capacidad sin equilibrar | C6: S&OP y Plan Maestro (Forecast to Plan) | D6: Sin S&OP, la capacidad (turnos, reservas, intercompany) se decide por intuición y a mano, y el desequilibrio se arregla con urgencias. | E6: Ineficiencia | F6: Transformación | G6: Horas de línea y turnos no ajustados a la carga / mes | H6: Horas de turno no ajustadas a la carga (h/mes) ↓ | I6: (valor-obj)*12*150 | J6: P2R-02 | K6: ✓ | L6: ✓ | M6: ✓ | N6: =COUNTIF(K6:M6,"✓") -> 3 | O6: —
A7: HT-P2R-04 | B7: Stock sin política clara | C7: S&OP y Plan Maestro (Forecast to Plan) | D7: Sin segmentación ni estrategia por material, sobra stock de unos y falta de otros, en producto terminado y en materias primas. | E7: Ineficiencia | F7: Circulante | G7: € de stock fuera de política (exceso y obsoleto) | H7: Cobertura de producto terminado (días) ↓ | I7: (valor-obj)*20000*0.08 | J7: P2R-03 | K7: ✓ | M7: ✓ | N7: =COUNTIF(K7:M7,"✓") -> 2 | O7: Ondupack
A8: HT-P2R-05 | B8: Fecha al cliente no fiable | C8: S&OP y Plan Maestro (Forecast to Plan) | D8: La fecha se promete sin comprobar disponibilidad, no se renegocia cuando no se llega y hay roturas en lo que debería estar en stock. | E8: Oportunidad | F8: — | G8: € de pedidos / mes entregados tarde o no servidos | H8: Pedidos entregados en la primera fecha confirmada (%) ↑ | I8: (obj-valor)/100*10000000 | J8: P2R-03, P2R-04 | K8: ✓ | M8: ✓ | N8: =COUNTIF(K8:M8,"✓") -> 2 | O8: Ondupack
A9: HT-P2R-06 | B9: Faltas tardías y gestionadas a mano | C9: Necesidades de Fabricación y MRP | D9: El MRP corre con poca frecuencia, las faltas se revisan todas a mano y acaban en compras y transportes urgentes. | E9: Ineficiencia | F9: Fuga de P&L | G9: € de sobrecoste urgente por faltas / mes | H9: Compras y transportes urgentes por faltas (nº/mes) ↓ | I9: (valor-obj)*12*400 | J9: P2R-05 | L9: ✓ | N9: =COUNTIF(K9:M9,"✓") -> 1 | O9: —
A10: HT-P2R-07 | B10: Necesidades poco fiables | C10: Necesidades de Fabricación y MRP | D10: Parámetros desactualizados, producto terminado y semielaborado sin sincronizar y agrupación de lotes a mano. | E10: Ineficiencia | F10: Circulante | G10: € de stock de semielaborado y materia prima por encima de la necesidad | H10: Cobertura de materias primas y semielaborado (días) ↓ | I10: (valor-obj)*8000*0.08 | J10: P2R-05 | L10: ✓ | M10: ✓ | N10: =COUNTIF(K10:M10,"✓") -> 2 | O10: —
A11: HT-P2R-08 | B11: Secuencia sin optimizar | C11: Programación | D11: Se secuencia a mano, sin capacidad finita y con la ruta por defecto. | E11: Ineficiencia | F11: Transformación | G11: Horas de cambio y de sobrecarga / semana | H11: Horas de cambio (h/semana) ↓ | I11: (valor-obj)*52*150 | J11: P2R-06 | K11: ✓ | L11: ✓ | M11: ✓ | N11: =COUNTIF(K11:M11,"✓") -> 3 | O11: —
A12: HT-P2R-09 | B12: Programa inestable | C12: Programación | D12: Sin zona congelada ni reglas de prioridad, las urgencias obligan a resecuenciar. | E12: Ineficiencia | F12: Transformación | G12: Resecuenciaciones / semana | H12: Resecuenciaciones dentro de la zona congelada (nº/semana) ↓ | I12: (valor-obj)*52*0.5*150 | J12: P2R-06 | K12: ✓ | L12: ✓ | M12: ✓ | N12: =COUNTIF(K12:M12,"✓") -> 3 | O12: —
A13: HT-P2R-10 | B13: Liberación sin control | C13: Liberación | D13: Se libera sin confirmar material, utillaje y aprovisionamiento a línea, y sin ventana de liberación. | E13: Ineficiencia | F13: Transformación | G13: Arranques fallidos / mes | H13: Arranques fallidos (nº/mes) ↓ | I13: (valor-obj)*12*2*150 | J13: P2R-07 | M13: ✓ | N13: =COUNTIF(K13:M13,"✓") -> 1 | O13: Ondupack
A14: HT-P2R-11 | B14: Servicio sin control | C14: Seguimiento y Control | D14: No hay KPIs formales de servicio ni de adherencia al programa, y los atrasos se ven cuando ya han ocurrido. | E14: Oportunidad | F14: — | G14: € de pedidos atrasados sin aviso / mes | H14: OTIF a fecha confirmada (%) ↑ | I14: (obj-valor)/100*10000000 | J14: P2R-08 | K14: ✓ | L14: ✓ | M14: ✓ | N14: =COUNTIF(K14:M14,"✓") -> 3 | O14: —
A15: HT-P2R-12 | B15: Ciclo sin aprendizaje | C15: Seguimiento y Control | D15: Las desviaciones no tienen análisis de causa ni vuelven a la previsión ni a los parámetros, y el seguimiento se hace a mano. | E15: Ineficiencia | F15: Transformación | G15: Desviaciones repetidas sin causa / mes | H15: Desviaciones repetidas sin causa (nº/mes) ↓ | I15: (valor-obj)*12*1*150 | J15: P2R-08 | K15: ✓ | M15: ✓ | N15: =COUNTIF(K15:M15,"✓") -> 2 | O15: Ondupack

Sheet Palancas
A1: Catálogo de palancas · P2R
A2: Transcrito de la aplicación el 29/10/2026 (8 palancas). €/año de referencia: vacío (el € sale de cada empresa) · confianza: por cuantificar. «Qué cambia», KPI y base expuesta del maestro.
A4: Código | B4: Palanca | C4: Qué cambia | D4: KPI | E4: Base expuesta | F4: Fase as-is | G4: €/año ref. | H4: Confianza | I4: Cura tipos | J4: Ondupet | K4: Ondupack | L4: MGT | M4: Aplicada en
A5: P2R-01 | B5: Gestión de la demanda | C5: Hay previsión, al menos de la demanda repetitiva; se cierra en fecha, se consensúa cada mes entre Comercial y Planificación, cubre el horizonte de las decisiones y se mide y corrige. | D5: Precisión y sesgo por familia · cambios tras el cierre | E5: € de stock medio de producto terminado expuesto al error de previsión | F5: Demanda y previsión (Forecast to Plan) | G5: — | H5: Por cuantificar | I5: HT-P2R-01 | J5: ✓ | K5: ✓ | L5: ✓ | M5: =COUNTIF(J5:L5,"✓") -> 3
A6: P2R-02 | B6: S&OP y plan de capacidad | C6: Demanda y capacidad se equilibran cada mes, con datos y con dirección: turnos, reservas de capacidad e intercompany se deciden con escenarios, no con urgencias. | D6: Ocupación real frente a planificada · horas extra no planificadas | E6: Horas de línea / año de turnos no ajustados a la carga | F6: S&OP y Plan Maestro (Forecast to Plan) | G6: — | H6: Por cuantificar | I6: HT-P2R-03 | J6: ✓ | K6: ✓ | L6: ✓ | M6: =COUNTIF(J6:L6,"✓") -> 3
A7: P2R-03 | B7: Política de inventario por segmento | C7: Cada material, de producto terminado y de materia prima, tiene segmento, estrategia y stock objetivo, revisados periódicamente. | D7: € de stock fuera de política · roturas | E7: € de stock de producto terminado por encima de la cobertura objetivo | F7: S&OP y Plan Maestro (Forecast to Plan) | G7: — | H7: Por cuantificar | I7: HT-P2R-04, HT-P2R-05 (×2) | J7: ✓ | L7: ✓ | M7: =COUNTIF(J7:L7,"✓") -> 2
A8: P2R-04 | B8: Promesa de fecha fiable | C8: La fecha al cliente se confirma con disponibilidad real y se renegocia en cuanto se sabe que no se llega. | D8: OTIF a fecha confirmada | E8: € de ventas / año en pedidos no entregados en la primera fecha confirmada | F8: S&OP y Plan Maestro (Forecast to Plan) | G8: — | H8: Por cuantificar | I8: HT-P2R-05 (×2) | J8: ✓ | L8: ✓ | M8: =COUNTIF(J8:L8,"✓") -> 2
A9: P2R-05 | B9: Planificación de materiales por excepción | C9: Las necesidades se calculan a tiempo, con parámetros vigentes y en todos los niveles, y el planificador solo atiende las excepciones críticas. | D9: € urgentes por faltas · faltas detectadas a tiempo | E9: € / año de compras y transportes urgentes por faltas · € de stock de materias primas y semielaborado por encima de la cobertura objetivo | F9: Necesidades de Fabricación y MRP | G9: — | H9: Por cuantificar | I9: HT-P2R-06, HT-P2R-07 | K9: ✓ | L9: ✓ | M9: =COUNTIF(J9:L9,"✓") -> 2
A10: P2R-06 | B10: Programación estable y optimizada | C10: El programa respeta la capacidad, minimiza los cambios y solo se modifica dentro de reglas: zona congelada y prioridades. | D10: Horas de cambio · adherencia al programa | E10: Horas de línea / año en cambios y resecuenciaciones evitables | F10: Programación | G10: — | H10: Por cuantificar | I10: HT-P2R-08, HT-P2R-09 | J10: ✓ | K10: ✓ | L10: ✓ | M10: =COUNTIF(J10:L10,"✓") -> 3
A11: P2R-07 | B11: Liberación controlada | C11: Una orden solo se libera con material, utillaje y aprovisionamiento a línea confirmados, y dentro de su ventana. | D11: Arranques fallidos | E11: Horas de línea / año perdidas en arranques fallidos | F11: Liberación | G11: — | H11: Por cuantificar | I11: HT-P2R-10 | L11: ✓ | M11: =COUNTIF(J11:L11,"✓") -> 1
A12: P2R-08 | B12: Control del servicio y mejora continua | C12: Servicio y adherencia se miden solos, los riesgos se avisan antes y cada desviación tiene causa y una acción que vuelve a la planificación. | D12: OTIF · desviaciones con causa | E12: € de ventas / año en pedidos fuera de OTIF · horas de línea / año perdidas en desviaciones repetidas | F12: Seguimiento y Control | G12: — | H12: Por cuantificar | I12: HT-P2R-11, HT-P2R-12 | J12: ✓ | K12: ✓ | L12: ✓ | M12: =COUNTIF(J12:L12,"✓") -> 3

Sheet Ondupet
A1: P2R × Ondupet · hallazgos, palancas e intervenciones
A2: Process owner: celda sin activar. Capacidad liberada que calcula la aplicación: 17,4 k€.
A4: Hallazgos | B4: =SUMPRODUCT((C7:C22<>"")/COUNTIF(C7:C22,C7:C22&"")) -> 9 | C4: Palancas | D4: =COUNTA(A7:A22) -> 6 | E4: Intervenciones | F4: =COUNTA(G7:G22) -> 15 | G4: De ellas, agentes | H4: =COUNTIF(H7:H22,"agente") -> 4 | I4: Capacidad (est.) | J4: =SUM(K7:K22) -> 17403
A6: Palanca | B6: Qué cambia | C6: Hallazgo | D6: Familia · naturaleza | E6: Anclaje (actividad · fase) | F6: Descripción del hallazgo | G6: Intervención | H6: De qué es | I6: Qué hay que hacer | J6: Caja que cambia | K6: Capacidad (est.)
A7: P2R-01 Gestión de la demanda | B7: Hay previsión, al menos de la demanda repetitiva; se cierra en fecha, se consensúa cada mes entre Comercial y Planificación, cubre el horizonte de las decisiones y se mide y corrige. | C7: INF-10 HT-P2R-01 · Demanda sin previsión fiable | D7: Ineficiencia · Circulante | E7: Previsión y Precisión · Demanda y previsión | F7: Previsión inestable: Comercial modifica la previsión a comienzo de mes, incluso con el material ya fabricado, sin comunicación formal ni cierre ni consenso, y nadie responde del stock que queda fabricado. | G7: ACC-01 · Calendario de previsión con día de cierre | H7: negocio | I7: Fijar un día de cierre mensual de la previsión y congelar el mes en curso. Después del cierre, cualquier cambio necesita la aprobación de Planificación y queda registrado con su motivo. Publicar el calendario del año. | J7: no cambia caja | K7: —
C8: INF-16 HT-P2R-01 · Demanda sin previsión fiable | D8: Ineficiencia · Circulante | E8: Previsión y Precisión · Demanda y previsión | F8: Previsión sin medición ni aprendizaje: la reunión mensual de accuracy existe pero no genera acciones, hay desviaciones grandes sin causa ni corrección y los agotados se registran de forma irregular. | G8: ACC-02 · Registro diario de agotados | H8: negocio | I8: Definir qué es un agotado y qué es un pedido rechazado, y registrarlos cada día en el sistema con su motivo, para que el histórico de demanda deje de estar distorsionado. | J8: no cambia caja | K8: —
G9: INT-01 · Análisis de las desviaciones de la demanda | H9: agente | I9: Cada mes analiza las familias fuera de umbral, explica la causa probable (agotado, pedido puntual, cliente nuevo, cambio de Comercial) y propone la corrección de los meses siguientes. Planificación y Comercial la aprueban en la reunión de consenso. | J9: Previsión y Precisión | K9: 903
A10: P2R-02 S&OP y plan de capacidad | B10: Demanda y capacidad se equilibran cada mes, con datos y con dirección: turnos, reservas de capacidad e intercompany se deciden con escenarios, no con urgencias. | C10: INF-11 HT-P2R-03 · Demanda y capacidad sin equilibrar | D10: Ineficiencia · Transformación | E10: Plan Maestro · S&OP y Plan Maestro | F10: Las necesidades se cargan sin comprobar la capacidad de extrusión y termoformado ni balancear entre líneas, y los temporales se calculan a mano. | G10: ACC-03 · Cálculo de % de saturación | H10: software | I10: Al cerrar la previsión, el sistema calcula el % de saturación de cada línea de extrusión y termoformado (previsión × rutas × tiempos de ciclo frente al calendario) y marca las que pasan del umbral. | J10: no cambia caja | K10: —
G11: ACC-04 · Revisión mensual de la capacidad de la planta | H11: negocio | I11: Tras el cierre de la previsión, Planificación presenta la carga frente a la capacidad y la dirección de planta decide turnos y balanceo con umbrales de ocupación acordados. Es el S&OP de planta mientras llega el de grupo. | J11: no cambia caja | K11: —
G12: ACC-05 · Cálculo automático de temporales | H12: software | I12: La reserva de ciclo por familia se calcula sola en cada cierre a partir de la previsión cerrada y los tiempos de ciclo. Planificación solo revisa los cambios en la reunión de consenso. | J12: no cambia caja | K12: —
G13: INT-02 · Propuestas de balanceo | H13: agente | I13: Agente que propone el reparto de turnos y de carga entre las líneas de extrusión y termoformado, con su impacto en horas y €. Planificación lo aprueba en la revisión mensual de capacidad. | J13: Plan Maestro | K13: 6000
A14: P2R-03 Política de inventario por segmento | B14: Cada material, de producto terminado y de materia prima, tiene segmento, estrategia y stock objetivo, revisados periódicamente. | C14: INF-13 HT-P2R-04 · Stock sin política clara | D14: Ineficiencia · Circulante | E14: Plan Maestro · S&OP y Plan Maestro | F14: No se calculan ABC ni estrategias MTS/MTO aunque GIO tiene la transacción, y el stock fabricado por cambios de previsión queda sin dueño. | G14: ACC-06 · Definir criterios ABC / estrategia | H14: negocio | I14: Definir ABC por valor, XYZ por variabilidad y la matriz que asigna a cada segmento MTS o MTO y su stock de seguridad. Comercial valida las estrategias. | J14: no cambia caja | K14: —
C15: OPP-02 HT-P2R-05 · Fecha al cliente no fiable | D15: Oportunidad · — | E15: Plan Maestro · S&OP y Plan Maestro | F15: Se mantiene la fecha del cliente aunque se sabe desde el principio que no se llega, y las dos fechas del pedido no se usan. (también en P2R-04) | G15: ACC-07 · Definir acciones para el stock sin rotación | H15: negocio | I15: Revisión mensual con Comercial del producto terminado sin movimiento: se decide venderlo, reprocesarlo o depreciarlo, y se imputa a quien lo originó cuando viene de un cambio de previsión fuera de plazo. | J15: no cambia caja | K15: —
G16: ACC-08 · Cálculo automático de días de stock | H16: software | I16: El sistema calcula la cobertura en días de stock de cada referencia y avisa de las que superan el objetivo de su segmento, para decidir a tiempo qué se deja de fabricar o se liquida. | J16: no cambia caja | K16: —
A17: P2R-04 Promesa de fecha fiable | B17: La fecha al cliente se confirma con disponibilidad real y se renegocia en cuanto se sabe que no se llega. | C17: OPP-02 HT-P2R-05 · Fecha al cliente no fiable | D17: Oportunidad · — | E17: Plan Maestro · S&OP y Plan Maestro | F17: Se mantiene la fecha del cliente aunque se sabe desde el principio que no se llega, y las dos fechas del pedido no se usan. (también en P2R-03) | G17: ACC-09 · Definir política de fecha confirmada | H17: negocio | I17: Cada pedido lleva fecha solicitada y fecha confirmada. Planificación confirma en un plazo fijo y, si sabe que no se llega, Comercial avisa al cliente con la nueva fecha; el aviso lo ejecuta O2C. | J17: no cambia caja | K17: —
G18: INT-03 · Propuesta de fechas de entrega viables para los pedidos y notas de carga | H18: agente | I18: Agente que calcula una fecha de entrega viable para cada pedido con la capacidad y los temporales, y propone las notas de carga. Comercial confirma la fecha al cliente por O2C. | J18: Plan Maestro | K18: 6000
A19: P2R-06 Programación estable y optimizada | B19: El programa respeta la capacidad, minimiza los cambios y solo se modifica dentro de reglas: zona congelada y prioridades. | C19: INF-12 HT-P2R-08 · Secuencia sin optimizar | D19: Ineficiencia · Transformación | E19: Programación | F19: La secuencia se hace totalmente a mano en GIO, sin optimizar los cambios de molde y altura y con la ruta por defecto sin reequilibrar. | G19: INT-04 · Determinación de urgencias | H19: agente | I19: Ante una petición de cambio, calcula el impacto (qué pedidos se retrasan y cuántos cambios extra supone), aplica las reglas de prioridad y propone la decisión. Si hay conflicto, la escala al árbitro con el impacto calculado. | J19: Programación | K19: 4500
C20: INF-14 HT-P2R-09 · Programa inestable | D20: Ineficiencia · Transformación | E20: Programación | F20: No hay zona congelada: los cambios de última hora llegan por teléfono y las prioridades se resuelven a mano; sin acuerdo, decide el director de planta.
A21: P2R-08 Control del servicio y mejora continua | B21: Servicio y adherencia se miden solos, los riesgos se avisan antes y cada desviación tiene causa y una acción que vuelve a la planificación. | C21: OPP-03 HT-P2R-11 · Servicio sin control | D21: Oportunidad · — | E21: Seguimiento y control · Seguimiento y Control | F21: No se mide el % de cumplimiento del servicio: el reporte diario de cargas atrasadas no es un KPI de OTIF y la fecha pensada para medir retrasos no se usa. | G21: ACC-10 · Análisis de atrasos de entregas | H21: negocio | I21: Cada atraso se clasifica con una lista cerrada de causas (previsión, capacidad, material, secuencia o cambio del cliente). Cada mes se revisan las principales con una acción y un responsable, y lo aprendido vuelve a la previsión o a los parámetros. | J21: no cambia caja | K21: —
C22: INF-15 HT-P2R-12 · Ciclo sin aprendizaje | D22: Ineficiencia · Transformación | E22: Seguimiento y control · Seguimiento y Control | F22: El reporte de atrasos se envía sin análisis de causa y los ajustes se hacen pedido a pedido, sin volver a la previsión ni a los parámetros. | G22: ACC-11 · Informe automático de pedidos / cargas en riesgo | H22: software | I22: Informe automático diario de los pedidos y cargas en riesgo de llegar tarde: sustituye al reporte manual de cargas atrasadas y avisa a Comercial antes de que ocurra el atraso. | J22: no cambia caja | K22: —
A24: Notas
A25: · INF-10 e INF-16 son del mismo tipo (HT-P2R-01) desde que se agruparon los de previsión: conviene fusionarlos para no contar dos veces su valor.
A26: · OPP-02 cuelga de P2R-03 y de P2R-04 (aviso ⚠ en la aplicación); lo cura P2R-04, así que se puede quitar de P2R-03.
A27: · En la aplicación la descripción de cada hallazgo es solo el nombre del tipo; aquí van las descripciones acordadas, para copiarlas.

Sheet MGT
A1: P2R × MGT · hallazgos, palancas e intervenciones
A2: Process owner: celda sin activar. La capacidad de los agentes sale a 0 € porque la celda aún no tiene dedicación de personas por fase.
A4: Hallazgos | B4: =SUMPRODUCT((C7:C23<>"")/COUNTIF(C7:C23,C7:C23&"")) -> 10 | C4: Palancas | D4: =COUNTA(A7:A23) -> 8 | E4: Intervenciones | F4: =COUNTA(G7:G23) -> 17 | G4: De ellas, agentes | H4: =COUNTIF(H7:H23,"agente") -> 6 | I4: Capacidad (est.) | J4: =SUM(K7:K23) -> 0
A6: Palanca | B6: Qué cambia | C6: Hallazgo | D6: Familia · naturaleza | E6: Anclaje (actividad · fase) | F6: Descripción del hallazgo | G6: Intervención | H6: De qué es | I6: Qué hay que hacer | J6: Caja que cambia | K6: Capacidad (est.)
A7: P2R-01 Gestión de la demanda | B7: Hay previsión, al menos de la demanda repetitiva; se cierra en fecha, se consensúa cada mes entre Comercial y Planificación, cubre el horizonte de las decisiones y se mide y corrige. | C7: INF-01 HT-P2R-01 · Demanda sin previsión fiable | D7: Oportunidad · — | E7: Demanda Intercompany · Demanda y previsión | F7: No hay previsión de ningún tipo, ni externa ni intercompany: se planifica solo con la cartera, y no se sabe si se registran las ventas perdidas. | G7: ACC-01 · Previsión de papel de Ondupack | H7: negocio | I7: Acordar con Ondupack que, en cada ciclo, envíe la previsión de papel de los ciclos siguientes por calidad y ancho, además del pedido firme 10 días antes. Es la otra mitad de la intervención «Previsión de papel compartida con MGT/PDA» de Ondupack. | J7: no cambia caja | K7: —
G8: ACC-02 · Previsión de los clientes externos repetitivos | H8: negocio | I8: Identificar con Comercial los clientes externos con consumo repetitivo y acordar con ellos una previsión no vinculante por calidad y ancho, revisada en cada ciclo. | J8: no cambia caja | K8: —
A9: P2R-02 S&OP y plan de capacidad | B9: Demanda y capacidad se equilibran cada mes, con datos y con dirección: turnos, reservas de capacidad e intercompany se deciden con escenarios, no con urgencias. | C9: INF-02 HT-P2R-03 · Demanda y capacidad sin equilibrar | D9: Ineficiencia · Transformación | E9: Carga de Capacidad · S&OP y Plan Maestro | F9: Los pedidos se cargan a capacidad infinita y la máquina trabaja siempre a 3 turnos a velocidad máxima; la duración de cada calidad en el ciclo se ajusta sobre la marcha, sin propuesta. | G9: ACC-03 · Política de llenado de capacidad | H9: negocio | I9: Decidir con Dirección qué se fabrica cuando sobra capacidad (referencias repetitivas con mínimo y máximo, sobre todo las de Ondupack) y cuándo compensa parar, comparando el coste de parada con el coste del stock. Sustituye a la regla de «3 turnos siempre». | J9: no cambia caja | K9: —
G10: ACC-04 · Revisión mensual de capacidad y ciclos | H10: negocio | I10: Reunión mensual de Joan Carles con Comercial (Albert) y Dirección: carga frente a capacidad de los próximos ciclos, duración de cada calidad y pedidos que no caben. | J10: no cambia caja | K10: —
G11: INT-01 · Agente de escenarios de ciclo | H11: agente | I11: Simula alternativas de duración y orden de las calidades, paradas y stock, y propone el ciclo con su impacto en coste y servicio. Planificación lo aprueba en la revisión mensual. | J11: Carga de Capacidad | K11: 0
A12: P2R-03 Política de inventario por segmento | B12: Cada material, de producto terminado y de materia prima, tiene segmento, estrategia y stock objetivo, revisados periódicamente. | C12: INF-03 HT-P2R-04 · Stock sin política clara | D12: Ineficiencia · Circulante | E12: Plan Fabricación · S&OP y Plan Maestro | F12: Se acumula stock de Ondupack en MGT, que lo va retirando poco a poco; lo fabricado de más no se ajusta en el pedido y las 3 turnos generan stock aunque todo se fabrica bajo pedido. | G12: ACC-05 · Pull system con Ondupack, con mínimo y máximo por referencia | H12: negocio | I12: Definir con Ondupack qué referencias se reponen por pull, con un mínimo y un máximo en MGT. Ondupack retira cada día de ese stock y MGT lo repone al combinar sus ciclos. | J12: no cambia caja | K12: —
C13: OPP-02 HT-P2R-05 · Fecha al cliente no fiable | D13: Oportunidad · — | E13: Plan Fabricación · S&OP y Plan Maestro | F13: Al entrar el pedido no se propone fecha porque la planificación no está integrada con Comercial, y las fechas de Ondupack no son fiables: marcan el inicio del ciclo y después cambian. (también en P2R-04) | G13: INT-02 · Agente de stock intercompany | H13: agente | I13: Cada mes revisa la cobertura de las referencias de Ondupack en MGT, propone ajustar mínimos y máximos y avisa del stock que se queda sin salida. | J13: Plan Fabricación | K13: 0
A14: P2R-04 Promesa de fecha fiable | B14: La fecha al cliente se confirma con disponibilidad real y se renegocia en cuanto se sabe que no se llega. | C14: OPP-02 HT-P2R-05 · Fecha al cliente no fiable | D14: Oportunidad · — | E14: Plan Fabricación · S&OP y Plan Maestro | F14: Al entrar el pedido no se propone fecha porque la planificación no está integrada con Comercial, y las fechas de Ondupack no son fiables: marcan el inicio del ciclo y después cambian. (también en P2R-03) | G14: INT-04 · Copiloto de plazos para Comercial | H14: agente | I14: Comercial pregunta «¿cuándo sale la próxima tirada de esta calidad y ancho?» y el copiloto responde con el plan de ciclos y la capacidad libre, sin llamar a Planificación. | J14: Demanda Externa | K14: 0
A15: P2R-05 Planificación de materiales por excepción | B15: Las necesidades se calculan a tiempo, con parámetros vigentes y en todos los niveles, y el planificador solo atiende las excepciones críticas. | C15: INF-04 HT-P2R-07 · Necesidades poco fiables | D15: Ineficiencia · Circulante | E15: Propuesta de Fabricación · Necesidades de Fabricación y MRP | F15: El MRP de materias primas se hace en un Excel; el de auxiliares, en SAP, se descuadra porque la entrada de báscula se registra después del consumo, y no se sabe cómo se planifica la bobina madre. | G15: ACC-06 · MRP de materias primas en SAP | H15: software | I15: Pasar el MRP de materias primas del Excel a SAP, como ya se hace con los auxiliares, alimentado con el plan de ciclos y con lead time, lote mínimo y stock de seguridad completos. | J15: no cambia caja | K15: —
G16: INT-03 · Agente de compras de materiales | H16: agente | I16: Revisa cada día los mensajes del MRP, propone las solicitudes de compra y avisa cuando el consumo se separa del plan. Marta Boyo y Joan Carles aprueban; el pedido sigue en P2P. | J16: MRP | K16: 0
A17: P2R-06 Programación estable y optimizada | B17: El programa respeta la capacidad, minimiza los cambios y solo se modifica dentro de reglas: zona congelada y prioridades. | C17: INF-05 HT-P2R-08 · Secuencia sin optimizar | D17: Ineficiencia · Transformación | E17: Programación | F17: El algoritmo de combinación no tiene en cuenta lo ya fabricado ni hay fecha límite de cartera, y la agrupación por calidad y ancho es manual salvo que se use su salida. | G17: ACC-07 · Algoritmo con lo ya fabricado y fecha límite de cartera | H17: software | I17: El algoritmo tiene en cuenta lo ya fabricado y el stock pull, y una fecha límite de cartera por ciclo. Su salida pasa a ser el estándar y la agrupación manual por calidad y ancho desaparece. | J17: no cambia caja | K17: —
C18: INF-06 HT-P2R-09 · Programa inestable | D18: Ineficiencia · Transformación | E18: Programación | F18: Las urgencias, también las de Ondupack fuera del plazo de 10 días, se encajan a mano, sin alertas ni zona congelada, y las prioridades se negocian caso a caso. | G18: INT-05 · Agente de urgencias | H18: agente | I18: Ante una urgencia, comprueba si cabe en el ciclo y qué pedidos y combinaciones se ven afectados, aplica las reglas y propone la decisión. Si hay conflicto, la escala con el impacto calculado. | J18: Programación | K18: 0
A19: P2R-07 Liberación controlada | B19: Una orden solo se libera con material, utillaje y aprovisionamiento a línea confirmados, y dentro de su ventana. | C19: INF-08 HT-P2R-10 · Liberación sin control | D19: Ineficiencia · Transformación | E19: Liberación de la Orden · Liberación | F19: No hay faltas por orden: el planificador comprueba a mano, en varios sitios, que hay material, sin ver cuándo llega, y la orden se entrega impresa en papel. | G19: ACC-11 · Disponibilidad de material por orden | H19: software | I19: El sistema muestra en cada orden si el material está y cuándo llega, a partir del MRP y de los pedidos de compra. Sustituye la comprobación manual en varios sitios. | J19: no cambia caja | K19: —
A20: P2R-08 Control del servicio y mejora continua | B20: Servicio y adherencia se miden solos, los riesgos se avisan antes y cada desviación tiene causa y una acción que vuelve a la planificación. | C20: OPP-03 HT-P2R-11 · Servicio sin control | D20: Oportunidad · — | E20: Seguimiento del servicio · Seguimiento y Control | F20: No hay pilar de servicio ni KPI: las incidencias se resuelven por llamada y la coordinación de entregas con Ondupack lleva unos 16 correos al día. | G20: ACC-08 · Pilar de servicio semanal | H20: negocio | I20: Reunión semanal fija entre MGT, Ondupack y Comercial: servicio, pedidos pendientes, atrasos y sus causas, y restos de pedidos antiguos por cerrar. | J20: no cambia caja | K20: —
C21: INF-07 HT-P2R-12 · Ciclo sin aprendizaje | D21: Ineficiencia · Transformación | E21: Seguimiento del servicio · Seguimiento y Control | F21: No se analizan desviaciones ni atrasos y las incidencias no dejan causa registrada. | G21: ACC-09 · KPI de servicio | H21: negocio | I21: Definir el OTIF contra fecha confirmada para clientes externos y para Ondupack, y publicarlo cada semana. | J21: no cambia caja | K21: —
G22: ACC-10 · Visibilidad de stock y cargas para Ondupack | H22: software | I22: Ondupack ve en línea el stock de MGT y la producción prevista, y pide las cargas desde ahí, en lugar de los unos 16 correos diarios. La carga la sigue ejecutando T2D. | J22: no cambia caja | K22: —
G23: INT-06 · Agente de coordinación de cargas con Ondupack | H23: agente | I23: Lee las peticiones de Ondupack, comprueba stock y plan, y propone la carga del día siguiente dentro del mínimo y máximo acordados. Joan Carles aprueba. | J23: Entregas a Ondupack y Cierre | K23: 0
A25: Notas
A26: · OPP-02 cuelga de P2R-03 y de P2R-04 (aviso ⚠ en P2R-03); lo cura P2R-04, así que se puede quitar de P2R-03.
A27: · P2R-05 no cura HT-P2R-06 en MGT (no está asignado), solo HT-P2R-07.
A28: · P2R-04 solo tiene el copiloto de plazos: sin la «Fecha confirmada por Planificación» (negocio) nada cambia cómo se promete la fecha, que es lo que describe OPP-02.
A29: · INF-08 menciona las órdenes impresas en papel, pero P2R-07 no tiene la «Orden digital a producción»; y el descuadre de báscula de INF-04 depende del proceso de inventario.
A30: · En la aplicación la descripción de cada hallazgo es solo el nombre del tipo; aquí van las descripciones acordadas, para copiarlas.

Sheet Ondupack Almendralejo
A1: P2R × Ondupack Almendralejo · hallazgos, palancas e intervenciones
A2: Process owner: Enrique Tejada. La capacidad de los agentes sale a 0 € porque la celda aún no tiene dedicación de personas por fase.
A4: Hallazgos | B4: =SUMPRODUCT((C7:C20<>"")/COUNTIF(C7:C20,C7:C20&"")) -> 7 | C4: Palancas | D4: =COUNTA(A7:A20) -> 5 | E4: Intervenciones | F4: =COUNTA(G7:G20) -> 14 | G4: De ellas, agentes | H4: =COUNTIF(H7:H20,"agente") -> 4 | I4: Capacidad (est.) | J4: =SUM(K7:K20) -> 0
A6: Palanca | B6: Qué cambia | C6: Hallazgo | D6: Familia · naturaleza | E6: Anclaje (actividad · fase) | F6: Descripción del hallazgo | G6: Intervención | H6: De qué es | I6: Qué hay que hacer | J6: Caja que cambia | K6: Capacidad (est.)
A7: P2R-01 Gestión de la demanda | B7: Hay previsión, al menos de la demanda repetitiva; se cierra en fecha, se consensúa cada mes entre Comercial y Planificación, cubre el horizonte de las decisiones y se mide y corrige. | C7: INF-01 HT-P2R-01 · Demanda sin previsión fiable | D7: Ineficiencia · Circulante | E7: Entrada de Pedidos y Fecha · Demanda y previsión | F7: No se usa previsión aunque hay clientes con consumo repetitivo, no se sabe qué parte de la demanda es de pedido firme, de stock o intercompany, y la demanda perdida no se registra en el sistema. | G7: ACC-01 · Integración de las referencias/clientes que vayan por previsión en GIO | H7: negocio | I7: Identificar con Comercial los clientes y referencias con consumo repetitivo, acordar con ellos una previsión no vinculante y cargarla en GIO para que la carga-capacidad y el CTP la tengan en cuenta. | J7: no cambia caja | K7: —
G8: ACC-02 · Registro de la demanda perdida en GIO | H8: software | I8: Cuando el cliente no acepta la fecha que propone el CTP, reduce la cantidad o se rechaza un pedido por capacidad, GIO obliga a registrar el motivo. | J8: no cambia caja | K8: —
A9: P2R-02 S&OP y plan de capacidad | B9: Demanda y capacidad se equilibran cada mes, con datos y con dirección: turnos, reservas de capacidad e intercompany se deciden con escenarios, no con urgencias. | C9: INF-06 HT-P2R-03 · Demanda y capacidad sin equilibrar | D9: Ineficiencia · Transformación | E9: Carga Capacidad · S&OP y Plan Maestro | F9: La 924 no alcanza los metros planificados y arrastra pedidos lanzados. La sobresaturación se detecta tarde: por las fechas de entrega o porque se llena el almacén intermedio. | G9: ACC-03 · Revisión mensual de capacidad y cuellos de botella | H9: negocio | I9: Reunión mensual Planificación–Producción–Comercial con la carga de los próximos 2–3 meses por máquina: decide turnos con los escenarios de 2 a 5, qué entra en la 924 y qué se desvía por ruta alternativa. | J9: no cambia caja | K9: —
G10: INT-01 · Agente de escenarios de capacidad | H10: agente | I10: Simula turnos, rutas alternativas para descargar la 924 y agrupaciones, y propone el plan con su impacto en servicio y coste. Planificación lo aprueba en la revisión mensual. | J10: Carga Capacidad | K10: 0
A11: P2R-05 Planificación de materiales por excepción | B11: Las necesidades se calculan a tiempo, con parámetros vigentes y en todos los niveles, y el planificador solo atiende las excepciones críticas. | C11: INF-02 HT-P2R-06 · Faltas tardías y gestionadas a mano | D11: Ineficiencia · Fuga de P&L | E11: Papel y Auxiliares · Necesidades de Fabricación y MRP | F11: La falta de materia prima es su primer problema. El papel se pide por consumo pasado y los auxiliares se reponen a mano; no hay MRP ni aviso de faltas por orden, y GIO solo ve el stock de papel. | G11: ACC-04 · Necesidad de papel calculada desde el plan | H11: software | I11: Calcular cada día la necesidad neta de papel a partir de la cartera planificada, la previsión y la lista de materiales, en lugar del consumo pasado, y avisar de las faltas por orden y por fecha. | J11: no cambia caja | K11: —
C12: INF-03 HT-P2R-07 · Necesidades poco fiables | D12: Ineficiencia · Circulante | E12: Papel y Auxiliares · Necesidades de Fabricación y MRP | F12: La necesidad de papel no sale del plan, sale del histórico. Las sustituciones se hacen a mano, los consumos se dan por diferencia de inventario cada mes y el maestro está incompleto (sin lote mínimo ni calendario). | G12: ACC-05 · Stock de papel fiable sin esperar al inventario mensual | H12: software | I12: Declarar el consumo real de papel por orden, que ya se puede trazar en GPO, en lugar de calcularlo por diferencia en el inventario mensual. El registro lo hace el proceso de inventario; aquí se usa. | J12: no cambia caja | K12: —
G13: ACC-06 · Previsión de papel compartida con MGT/PDA/PAPRESA | H13: negocio | I13: En cada ciclo, Ondupack envía a MGT, PDA y Papresa la previsión de papel de los próximos ciclos por calidad y ancho, además del pedido firme 10 días antes. El pedido sigue yendo por P2P. | J13: no cambia caja | K13: —
G14: ACC-07 · Faltas de materia prima | H14: agente | I14: Cada día revisa las faltas por orden, propone la acción (adelantar el pedido a MGT, usar un sustituto aprobado o mover la orden) y prepara el aviso a Compras. Planificación aprueba. | J14: no cambia caja | K14: —
A15: P2R-06 Programación estable y optimizada | B15: El programa respeta la capacidad, minimiza los cambios y solo se modifica dentro de reglas: zona congelada y prioridades. | C15: INF-04 HT-P2R-08 · Secuencia sin optimizar | D15: Ineficiencia · Transformación | E15: Onduladora · Programación | F15: La combinación de onduladora y la secuencia de converting no se optimizan; la optimización está aplazada hasta estabilizar los datos. Se repiten maestros fabricados en la misma semana. | G15: ACC-11 · Algoritmo de combinación | H15: software | I15: Propone las combinaciones por canal minimizando trim y cambios, y agrupa las referencias que hoy se repiten en la misma semana. El planificador las revisa y aprueba. Ya está en el plan de sistemas. | J15: no cambia caja | K15: —
C16: INF-05 HT-P2R-09 · Programa inestable | D16: Ineficiencia · Transformación | E16: Onduladora · Programación | F16: No hay zona congelada: los cambios del cliente se aceptan por email mientras el pedido no esté fabricado, las urgencias se resuelven llamando y no se registra la causa de las reprogramaciones. | G16: INT-03 · Agente de urgencias y cambios | H16: agente | I16: Ante un cambio del cliente o una urgencia, calcula el impacto (pedidos desplazados, cambios extra y saturación del almacén intermedio), aplica el criterio de urgencia y propone la decisión; si hay conflicto, la escala. | J16: Converting | K16: 0
A17: P2R-08 Control del servicio y mejora continua | B17: Servicio y adherencia se miden solos, los riesgos se avisan antes y cada desviación tiene causa y una acción que vuelve a la planificación. | C17: OPP-01 HT-P2R-11 · Servicio sin control | D17: Oportunidad · — | E17: Revisión Semanal · Seguimiento y Control | F17: Falta un KPI oficial de servicio: Dirección y Comercial todavía no han decidido cuál usar ni contra qué fecha medirlo. | G17: ACC-08 · KPI oficial de servicio | H17: negocio | I17: Que Dirección y Comercial decidan el KPI oficial (recomendado: OTIF contra fecha confirmada por el CTP, pedido completo) y su objetivo, y publicarlo cada semana. | J17: no cambia caja | K17: —
G18: ACC-09 · Reunión semanal con KPIs y causas | H18: negocio | I18: La reunión semanal de planificación Ondupack/Navalmoral incorpora el OTIF, la adherencia y las principales causas de atraso y de reprogramación, cada una con su acción y su responsable. | J18: no cambia caja | K18: —
G19: ACC-10 · Copiloto de estado de pedidos | H19: software | I19: Responde a Call center y a Comercial «¿cuándo sale el pedido X?» y «¿por qué va tarde?» con los datos de GIO, sin cambiar nada. | J19: no cambia caja | K19: —
G20: INT-02 · Agente de causa raíz | H20: agente | I20: Clasifica cada atraso y desviación (velocidad, OEE, falta de papel, cambio del cliente o saturación), propone la acción y el ajuste de parámetros. Planificación aprueba. | J20: Seguimiento del Servicio | K20: 0
A22: Notas
A23: · El tipo HT-P2R-01 es ahora Oportunidad, pero INF-01 sigue como Ineficiencia · Circulante (igual que INF-10 e INF-16 en Ondupet).
A24: · ACC-07 es un agente que no cambia ninguna caja: si se marca sobre «Autorizar la liberación con material pendiente», aparecerá en el to-be y tendrá capacidad.
A25: · HT-P2R-12 no está asignado en esta celda, así que P2R-08 solo cura OPP-01.

Sheet Fichas de hallazgo
A1: Fichas de hallazgo por empresa · campos del formulario (sin cuantificación)
A2: Detectado en: «aquí mismo» en todos. La métrica es el volumen expuesto que hoy se puede medir en cada empresa (sustituye a la heredada del tipo antiguo). Esfuerzo e impacto de 1 (bajo) a 5 (alto), como en la aplicación. La última columna dice qué hay que cambiar en la aplicación.
A4: Empresa | B4: ID | C4: Tipo de hallazgo | D4: Familia | E4: Naturaleza | F4: Anclaje (bloque) | G4: Fase | H4: Descripción | I4: Métrica (volumen expuesto) | J4: Esfuerzo | K4: Impacto | L4: Qué cambiar en la aplicación
A5: Ondupet | B5: INF-10 | C5: HT-P2R-01 · Demanda sin previsión fiable | D5: Ineficiencia | E5: Circulante | F5: Previsión y Precisión | G5: Demanda y previsión | H5: Comercial modifica la previsión a comienzo de mes, incluso con el material ya fabricado, sin comunicación formal ni cierre ni consenso, y nadie responde del stock fabricado. Además, la reunión de accuracy no genera acciones y los agotados se registran de forma irregular. | I5: € / mes de previsión cambiada tras el inicio del mes o sin consensuar | J5: 2 | K5: 5 | L5: Pegar esta descripción, que ya incluye INF-16.
A6: Ondupet | B6: INF-16 | C6: HT-P2R-01 · Demanda sin previsión fiable | D6: Ineficiencia | E6: Circulante | F6: Previsión y Precisión | G6: Demanda y previsión | J6: — | K6: — | L6: Fusionar en INF-10 y desactivar en Ondupet: es el mismo tipo.
A7: Ondupet | B7: INF-11 | C7: HT-P2R-03 · Demanda y capacidad sin equilibrar | D7: Ineficiencia | E7: Transformación | F7: Plan Maestro | G7: S&OP y Plan Maestro | H7: Las necesidades se cargan sin comprobar la capacidad de extrusión y termoformado ni balancear entre líneas, y los temporales se calculan a mano. | I7: Horas de línea / año de extrusión y termoformado planificadas sin cruzar carga y capacidad | J7: 3 | K7: 4
A8: Ondupet | B8: INF-13 | C8: HT-P2R-04 · Stock sin política clara | D8: Ineficiencia | E8: Circulante | F8: Plan Maestro | G8: S&OP y Plan Maestro | H8: No se calculan ABC ni estrategias MTS/MTO aunque GIO tiene la transacción, y el stock fabricado por cambios de previsión queda sin dueño. | I8: € de stock medio de producto terminado sin ABC ni estrategia | J8: 2 | K8: 3
A9: Ondupet | B9: OPP-02 | C9: HT-P2R-05 · Fecha al cliente no fiable | D9: Oportunidad | E9: — | F9: Plan Maestro | G9: S&OP y Plan Maestro | H9: Se mantiene la fecha del cliente aunque se sabe desde el principio que no se llega, y las dos fechas del pedido no se usan. | I9: € de ventas / año en pedidos entregados después de la fecha del cliente | J9: 3 | K9: 4
A10: Ondupet | B10: INF-12 | C10: HT-P2R-08 · Secuencia sin optimizar | D10: Ineficiencia | E10: Transformación | F10: Programación | G10: Programación | H10: La secuencia se hace totalmente a mano en GIO, sin optimizar los cambios de molde y altura y con la ruta por defecto sin reequilibrar. | I10: Horas de línea / año en cambios de molde y altura | J10: 5 | K10: 4
A11: Ondupet | B11: INF-14 | C11: HT-P2R-09 · Programa inestable | D11: Ineficiencia | E11: Transformación | F11: Programación | G11: Programación | H11: No hay zona congelada: los cambios de última hora llegan por teléfono y las prioridades se resuelven a mano; sin acuerdo, decide el director de planta. | I11: Cambios de última hora / año dentro del programa | J11: 1 | K11: 3
A12: Ondupet | B12: OPP-03 | C12: HT-P2R-11 · Servicio sin control | D12: Oportunidad | E12: — | F12: Seguimiento y control | G12: Seguimiento y Control | H12: No se mide el % de cumplimiento del servicio: el reporte diario de cargas atrasadas no es un KPI de OTIF y la fecha pensada para medir retrasos no se usa. | I12: € de ventas / año en pedidos atrasados (reporte diario de cargas atrasadas) | J12: 2 | K12: 3
A13: Ondupet | B13: INF-15 | C13: HT-P2R-12 · Ciclo sin aprendizaje | D13: Ineficiencia | E13: Transformación | F13: Seguimiento y control | G13: Seguimiento y Control | H13: El reporte de atrasos se envía sin análisis de causa y los ajustes se hacen pedido a pedido, sin volver a la previsión ni a los parámetros. | I13: Atrasos / año sin análisis de causa | J13: 1 | K13: 2
A14: MGT | B14: INF-01 | C14: HT-P2R-01 · Demanda sin previsión fiable | D14: Ineficiencia | E14: Circulante | F14: Demanda Intercompany | G14: Demanda y previsión | H14: No hay previsión de ningún tipo, ni externa ni intercompany: se planifica solo con la cartera, y no se sabe si se registran las ventas perdidas. | I14: t / año de papel (Ondupack y clientes repetitivos) planificadas sin previsión | J14: 3 | K14: 4 | L14: Cambiar la familia a Ineficiencia · Circulante, como el tipo.
A15: MGT | B15: INF-02 | C15: HT-P2R-03 · Demanda y capacidad sin equilibrar | D15: Ineficiencia | E15: Transformación | F15: Carga de Capacidad | G15: S&OP y Plan Maestro | H15: Los pedidos se cargan a capacidad infinita y la máquina trabaja siempre a 3 turnos a velocidad máxima; la duración de cada calidad en el ciclo se ajusta sobre la marcha, sin propuesta. | I15: Horas / año de máquina a 3 turnos sin cartera que los llene | J15: 3 | K15: 4
A16: MGT | B16: INF-03 | C16: HT-P2R-04 · Stock sin política clara | D16: Ineficiencia | E16: Circulante | F16: Plan Fabricación | G16: S&OP y Plan Maestro | H16: Se acumula stock de Ondupack en MGT, que lo va retirando poco a poco; lo fabricado de más no se ajusta en el pedido y las 3 turnos generan stock aunque todo se fabrica bajo pedido. | I16: € de stock de Ondupack en MGT | J16: 3 | K16: 5
A17: MGT | B17: OPP-02 | C17: HT-P2R-05 · Fecha al cliente no fiable | D17: Oportunidad | E17: — | F17: Demanda Externa | G17: Demanda y previsión | H17: Al entrar el pedido no se propone fecha porque la planificación no está integrada con Comercial, y las fechas de Ondupack no son fiables: marcan el inicio del ciclo y después cambian. | I17: € de ventas / año en pedidos entregados después de la fecha pedida por el cliente | J17: 4 | K17: 3 | L17: Cambiar el anclaje a Demanda Externa: es donde se da (o no) la fecha.
A18: MGT | B18: INF-04 | C18: HT-P2R-07 · Necesidades poco fiables | D18: Ineficiencia | E18: Circulante | F18: MRP | G18: Necesidades de Fabricación y MRP | H18: El MRP de materias primas se hace en un Excel; el de auxiliares, en SAP, se descuadra porque la entrada de báscula se registra después del consumo, y no se sabe cómo se planifica la bobina madre. | I18: € de stock medio de materias primas y auxiliares | J18: 3 | K18: 3 | L18: Cambiar el anclaje a MRP: el problema es el MRP, no la propuesta de PT.
A19: MGT | B19: INF-05 | C19: HT-P2R-08 · Secuencia sin optimizar | D19: Ineficiencia | E19: Transformación | F19: Programación | G19: Programación | H19: El algoritmo de combinación no tiene en cuenta lo ya fabricado ni hay fecha límite de cartera, y la agrupación por calidad y ancho es manual salvo que se use su salida. | I19: Horas / año de máquina en cambios de calidad y ancho | J19: 3 | K19: 4
A20: MGT | B20: INF-06 | C20: HT-P2R-09 · Programa inestable | D20: Ineficiencia | E20: Transformación | F20: Programación | G20: Programación | H20: Las urgencias, también las de Ondupack fuera del plazo de 10 días, se encajan a mano, sin alertas ni zona congelada, y las prioridades se negocian caso a caso. | I20: Urgencias / año encajadas a mano en el ciclo | J20: 1 | K20: 3
A21: MGT | B21: INF-08 | C21: HT-P2R-10 · Liberación sin control | D21: Ineficiencia | E21: Transformación | F21: Liberación de la Orden | G21: Liberación | H21: No hay faltas por orden: el planificador comprueba a mano, en varios sitios, que hay material, sin ver cuándo llega, y la orden se entrega impresa en papel. | I21: Órdenes / año liberadas con comprobación manual de material | J21: 3 | K21: 2
A22: MGT | B22: OPP-03 | C22: HT-P2R-11 · Servicio sin control | D22: Oportunidad | E22: — | F22: Seguimiento del servicio | G22: Seguimiento y Control | H22: No hay pilar de servicio ni KPI: las incidencias se resuelven por llamada y la coordinación de entregas con Ondupack lleva unos 16 correos al día. | I22: € de ventas / año en pedidos entregados tarde (incluido Ondupack) | J22: 3 | K22: 3
A23: MGT | B23: INF-07 | C23: HT-P2R-12 · Ciclo sin aprendizaje | D23: Ineficiencia | E23: Transformación | F23: Seguimiento del servicio | G23: Seguimiento y Control | H23: No se analizan desviaciones ni atrasos y las incidencias no dejan causa registrada. | I23: Incidencias / año resueltas sin causa registrada | J23: 1 | K23: 2
A24: Ondupack Almendralejo | B24: INF-01 | C24: HT-P2R-01 · Demanda sin previsión fiable | D24: Ineficiencia | E24: Circulante | F24: Entrada de Pedidos y Fecha | G24: Demanda y previsión | H24: No se usa previsión aunque hay clientes con consumo repetitivo, no se sabe qué parte de la demanda es de pedido firme, de stock o intercompany, y la demanda perdida no se registra en el sistema. | I24: € de ventas / año de clientes y referencias repetitivas planificadas sin previsión | J24: 3 | K24: 3
A25: Ondupack Almendralejo | B25: INF-06 | C25: HT-P2R-03 · Demanda y capacidad sin equilibrar | D25: Ineficiencia | E25: Transformación | F25: Carga Capacidad | G25: S&OP y Plan Maestro | H25: La 924 no alcanza los metros planificados y arrastra pedidos lanzados. La sobresaturación se detecta tarde: por las fechas de entrega o porque se llena el almacén intermedio. | I25: Horas / año de la 924 planificadas por encima de lo que produce | J25: 2 | K25: 5
A26: Ondupack Almendralejo | B26: INF-02 | C26: HT-P2R-06 · Faltas tardías y gestionadas a mano | D26: Ineficiencia | E26: Fuga de P&L | F26: Papel y Auxiliares | G26: Necesidades de Fabricación y MRP | H26: La falta de materia prima es su primer problema. El papel se pide por consumo pasado y los auxiliares se reponen a mano; no hay MRP ni aviso de faltas por orden, y GIO solo ve el stock de papel. | I26: Órdenes / año liberadas con material pendiente | J26: 4 | K26: 5
A27: Ondupack Almendralejo | B27: INF-03 | C27: HT-P2R-07 · Necesidades poco fiables | D27: Ineficiencia | E27: Circulante | F27: Papel y Auxiliares | G27: Necesidades de Fabricación y MRP | H27: La necesidad de papel no sale del plan, sale del histórico. Las sustituciones se hacen a mano, los consumos se dan por diferencia de inventario cada mes y el maestro está incompleto (sin lote mínimo ni calendario). | I27: € de stock medio de papel | J27: 4 | K27: 3
A28: Ondupack Almendralejo | B28: INF-04 | C28: HT-P2R-08 · Secuencia sin optimizar | D28: Ineficiencia | E28: Transformación | F28: Onduladora | G28: Programación | H28: La combinación de onduladora y la secuencia de converting no se optimizan; la optimización está aplazada hasta estabilizar los datos. Se repiten maestros fabricados en la misma semana. | I28: Horas / año de onduladora y converting en cambios | J28: 4 | K28: 4
