Workbook

Sheet Portada
B2: Modelo de planificación corporativo · CL Grupo Industrial
B3: Corporativo define procesos, roles, personas, políticas y KPIs; cada planta ejecuta.
B5: Origen de los datos | C5: Datos del equipo · export de la herramienta · 2026-10-08 · incluye: Análisis E2E de Ondupet, Necesidades de Ondupet y plan de acción 2027-2028
B6: Generado | C6: 08/10/2026
B7: Dónde se edita | C7: En la herramienta Modelo_Planificacion_CL.html; este Excel es una foto para revisar y compartir.
B9: Contenido
B10: Procesos | C10: Catálogo de procesos y actividades de planificación | D10: =COUNTA(Procesos!B:B)-1 -> 44 | E10: actividades
B11: Flujos | C11: Flujos de proceso as-is y to-be por empresa: pasos, responsables y conexiones | D11: =COUNT(Flujos!D:D) -> 103 | E11: cajas
B12: Notas | C12: Notas por empresa y actividad: situación actual, quién, problemas y propuesta | D12: =COUNTA(Notas!E:E)-1-COUNTIF(Notas!E:E,"Sin revisar") -> 22 | E12: actividades revisadas
B13: Madurez | C13: Situación por empresa y proceso
B14: RACI | C14: Matriz RACI por rol, con revisión automática de cada fila | D14: =COUNTIF(RACI!S:S,"OK") -> 44 | E14: filas correctas
B15: RACI as-is | C15: Cómo se hace hoy en cada empresa y diferencias con el estándar | D15: =COUNTA('RACI as-is'!C:C)-1 -> 14 | E15: filas
B16: Roles | C16: Fichas de rol: misión, responsabilidades, qué decide y KPIs | D16: =COUNTA(Roles!A:A)-1 -> 15 | E16: roles
B17: Asignación | C17: Titular y suplente de cada rol en cada empresa | D17: =COUNTA(Asignación!C:C)-1 -> 21 | E17: roles con titular
B18: Organigramas | C18: Organigramas as-is y to-be de cada empresa: puesto, persona y dependencias | D18: =COUNTA(Organigramas!D:D)-1 -> 60 | E18: puestos
B19: Empresas | C19: Perímetro: empresas y plantas | D19: =COUNTA(Empresas!A:A)-1 -> 7 | E19: empresas
B20: Políticas | C20: Políticas de planificación: estándar corporativo y parámetros por planta | D20: =COUNTA(Políticas!A:A)-1 -> 10 | E20: políticas
B21: KPIs | C21: Cuadro de mando común | D21: =COUNTA(KPIs!A:A)-1 -> 12 | E21: KPIs
B22: Reuniones | C22: Cadencia de planificación del grupo | D22: =COUNTA(Reuniones!A:A)-1 -> 0 | E22: reuniones
B23: Decisiones | C23: Decisiones que hay que cerrar con dirección | D23: =COUNTIF(Decisiones!F:F,"Abierta") -> 0 | E23: abiertas
B24: Plan | C24: Plan de acción: acciones por fase, empresa, responsable y fechas | D24: =COUNTA(Plan!B:B)-1 -> 46 | E24: acciones
B25: Gantt | C25: Cronograma mensual del plan de acción (se calcula desde la hoja Plan) | D25: =COUNTIF(Plan!G:G,"Hito") -> 10 | E25: hitos
B27: Leyenda RACI
B28: A | C28: Decide y responde del resultado (una sola por actividad)
B29: R | C29: Lo ejecuta
B30: A/R | C30: Decide y además lo ejecuta
B31: C | C31: Se le consulta antes
B32: I | C32: Se le informa después

Sheet Notas
A1: Empresa | B1: Proceso | C1: ID | D1: Actividad | E1: Situación | F1: Quién lo hace hoy | G1: Herramienta | H1: Frecuencia real | I1: Horas/semana | J1: Cómo se hace hoy | K1: Problemas | L1: Propuesta | M1: Prioridad | N1: Notas | O1: Origen
A2: Corporativo · Planificación | B2: Gobierno y S&OP | C2: G.1 | D2: Modelo de procesos y manual de planificación | E2: Sin revisar | O2: Catálogo
A3: Corporativo · Planificación | B3: Gobierno y S&OP | C3: G.2 | D3: Políticas de planificación | E3: Sin revisar | O3: Catálogo
A4: Corporativo · Planificación | B4: Gobierno y S&OP | C4: G.3 | D4: S&OP mensual del grupo | E4: Sin revisar | O4: Catálogo
A5: Corporativo · Planificación | B5: Gobierno y S&OP | C5: G.4 | D5: Objetivos y revisión de KPIs | E5: Sin revisar | O5: Catálogo
A6: Corporativo · Planificación | B6: Gobierno y S&OP | C6: G.5 | D6: Roles, personas, suplencias y formación | E6: Sin revisar | O6: Catálogo
A7: Corporativo · Planificación | B7: Gobierno y S&OP | C7: G.6 | D7: Gestión de cambios y prioridad de desarrollos | E7: Sin revisar | O7: Catálogo
A8: Corporativo · Planificación | B8: Dato maestro | C8: 1.1 | D8: Datos de planificación del material | E8: Sin revisar | O8: Catálogo
A9: Corporativo · Planificación | B9: Dato maestro | C9: 1.2 | D9: Segmentación ABC/XYZ y estrategia MTS/MTO | E9: Sin revisar | O9: Catálogo
A10: Corporativo · Planificación | B10: Dato maestro | C10: 1.3 | D10: Velocidades, tiempos de cambio y rutas | E10: Sin revisar | O10: Catálogo
A11: Corporativo · Planificación | B11: Dato maestro | C11: 1.4 | D11: Calendario de turnos, días y paradas | E11: Sin revisar | O11: Catálogo
A12: Corporativo · Planificación | B12: Dato maestro | C12: 1.5 | D12: Auditoría de calidad del dato | E12: Sin revisar | O12: Catálogo
A13: Corporativo · Planificación | B13: Demanda | C13: 2.1 | D13: Previsión de demanda | E13: Sin revisar | O13: Catálogo
... A51: Ondupet | B51: Gobierno y S&OP | C51: G.6 | D51: Gestión de cambios y prioridad de desarrollos | E51: Sin revisar | O51: Catálogo
A52: Ondupet | B52: Dato maestro | C52: 1.1 | D52: Datos de planificación del material | E52: Estándar propio | F52: Monica Gordillo | G52: GIO | H52: Bajo demanda (alta de material nuevo) | J52: Monica Gordillo crea los materiales: como es de Comercial, es quien antes se entera de que hace falta uno. Consulta con Calidad las características técnicas, pero no pregunta a Planificación qué estrategia debe llevar. | K52: Planificación no participa en el alta: el material llega sin estrategia (MTS/MTO, ABC) ni ruta revisada. Duda abierta: ¿se consulta a Producción y Mantenimiento la ruta por defecto? | L52: Alta con plantilla única: Comercial lo solicita, Calidad fija las características y Dato maestro asigna estrategia y ruta consultando a Planificación y Producción. Antes de crear, se comprueba que no haya duplicados. | M52: Media | O52: Catálogo
A53: Ondupet | B53: Dato maestro | C53: 1.2 | D53: Segmentación ABC/XYZ y estrategia MTS/MTO | E53: No se hace | F53: Nadie | G53: GIO | H53: Nunca | I53: 0 | J53: NO SE HACE | K53: Falta de coordinación y seguimiento entre planificación y comercial | L53: Cada tres meses debe haber revisión por parte de comercial y planificación para revisar estrategias de productos ya creados y de nueva creación | M53: Alta | N53: Tienen transacción preparada para calculo automático de ABC y estrategias | O53: Catálogo
A54: Ondupet | B54: Dato maestro | C54: 1.3 | D54: Velocidades, tiempos de cambio y rutas | E54: Estándar propio | G54: GIO | H54: Solo al dar de alta; las rutas no se revisan | J54: Las velocidades y los tiempos de cambio dependen del molde, que es un dato fijo del dato maestro. Por eso necesitan mucho menos mantenimiento que en otras plantas. | K54: Las rutas no se actualizan con la carga de capacidad del mes, así que la carga entre máquinas no se equilibra. | L54: Cada mes, Programación revisa las rutas por defecto con la carga del mes, consultando a Producción. Velocidades y tiempos de cambio se revisan solo si cambia el molde o hay desviaciones frente a lo real. | M54: Media | O54: Catálogo
A55: Ondupet | B55: Dato maestro | C55: 1.4 | D55: Calendario de turnos, días y paradas | E55: Sin revisar | O55: Catálogo
A56: Ondupet | B56: Dato maestro | C56: 1.5 | D56: Auditoría de calidad del dato | E56: No se hace | F56: Nadie (correcciones puntuales de Monica Gordillo y su equipo) | G56: GIO · campo «material reemplazante» | H56: Nunca; solo correcciones puntuales | J56: No hay auditoría ni estándar para detectar duplicados, porque no está claro qué características definen un material. Cuando Monica o alguien de su equipo encuentra uno, lo corrige con el campo «material reemplazante», que une el duplicado con el material definitivo sin perder el histórico de ventas ni de producción. | K56: Los duplicados se encuentran por casualidad: no hay análisis del dato maestro ni un criterio de qué define un material. | L56: Definir qué características identifican un material y hacer una auditoría mensual (duplicados, datos incompletos e incoherencias) con su KPI. Se sigue usando «material reemplazante» para unir materiales sin perder histórico. | M56: Media | O56: Catálogo
A57: Ondupet | B57: Demanda | C57: 2.1 | D57: Previsión de demanda | E57: Estándar propio | F57: Manuel Jesus Trinidad | H57: Mensual, sin día de cierre | J57: Cada mes, Manuel Jesus Trinidad carga la previsión de cada material: como mínimo, el mes en curso y los tres siguientes. | K57: No hay día límite para cerrar la previsión. La del mes en curso se cambia sin consultar a Planificación, incluso cuando el material ya está fabricado (no debería estar permitido). | L57: Calendario mensual con día límite de cierre: Planificación propone la previsión estadística y Comercial la ajusta. Después del cierre, el mes en curso queda congelado y cualquier cambio necesita la aprobación de Planificación. | M57: Alta | O57: Catálogo
A58: Ondupet | B58: Demanda | C58: 2.2 | D58: Consenso de la previsión con Comercial | E58: No se hace | F58: Nadie | H58: Nunca | J58: No hay un estándar para que Planificación y Comercial se pongan de acuerdo en qué se va a fabricar. Planificación fabrica lo que diga la previsión (descontando stock, órdenes lanzadas…) y con ella genera los temporales. | K58: No hay plan de demanda acordado: si la previsión es mala, lo son también lo fabricado y los plazos que se dan. | L58: Reunión mensual de consenso (Comercial, Planificación y S&OP) tras cerrar la previsión, que incluya la revisión de temporales (2.5). Si no hay acuerdo, decide S&OP. | M58: Alta | O58: Catálogo
A59: Ondupet | B59: Demanda | C59: 2.3 | D59: Demanda perdida (agotados) | E59: Informal | F59: Monica Gordillo y su equipo | H59: Irregular | J59: Se va de un extremo a otro: épocas con muchos agotados registrados y 2-3 meses sin registrar ninguno, aunque haya roturas. | K59: No está claro qué es un agotado, así que el dato no sirve para corregir la previsión. | L59: Definir qué es un agotado (pedido no servido o rechazado por falta de stock o de plazo), registrarlo a diario con un motivo codificado y revisarlo en el ciclo mensual de previsión. | M59: Media | O59: Catálogo
A60: Ondupet | B60: Demanda | C60: 2.4 | D60: Precisión y sesgo de la previsión | E60: Informal | F60: Manuel Jesus Trinidad y Victoriano Perez | H60: Reunión mensual | J60: Hay una reunión mensual de accuracy entre Manuel Jesus Trinidad y Victoriano Perez, pero Comercial no se implica y Planificación no la impulsa. | K60: Se ven desviaciones enormes en algunos materiales y no se hace nada. | L60: KPI mensual de precisión y sesgo por familia y material. Los diez peores se ven en la reunión de consenso y cada desviación tiene responsable y acción, que se revisa al mes siguiente. | M60: Media | O60: Catálogo
A61: Ondupet | B61: Demanda | C61: 2.5 | D61: Revisión de temporales | E61: Informal | F61: Victoriano Perez | H61: Mensual, sin revisión conjunta | J61: Planificación genera los temporales (previsiones de fabricación) a partir de la previsión de Comercial. Sirven para reservar tiempo de cada familia en el ciclo y poder dar plazos en la consulta de plazos. | K61: No se revisan con Comercial ni con un criterio común: si la previsión no es buena, los plazos que se dan tampoco. | L61: Revisión mensual de los temporales con la previsión ya consensuada, dentro de la reunión de consenso (2.2). | M61: Alta | N61: Del análisis E2E: falta decidir si es un apartado propio o forma parte de 2.2 (consenso de la previsión). | O61: Propio de la planta
A62: Ondupet | B62: Cartera | C62: 3.1 | D62: Revisión diaria de la cartera | E62: Estándar propio | F62: Monica Gordillo (Comercial) y Victoriano Perez (Planificación), por separado | H62: Diaria | J62: Cada día, Comercial y Planificación revisan por separado la cartera de pedidos, el stock disponible y las cargas, y lo ponen en común en la reunión de producción. | K62: No hay acuerdo sobre las fechas de entrega de cargas y pedidos: aunque Planificación avise de que no llega a la fecha del cliente, no se cambia. Y eso que el pedido tiene dos fechas: la que pidió el cliente y otra para medir retrasos. | L62: Una sola revisión con una sola fuente de datos. Planificación confirma una fecha viable y Comercial la negocia con el cliente. Se usan las dos fechas del pedido: la solicitada para medir el servicio y la confirmada para planificar. | M62: Alta | O62: Catálogo
A63: Ondupet | B63: Cartera | C63: 3.2 | D63: Cargas vinculadas a pedidos | E63: Estándar propio | F63: Monica Gordillo y su equipo (Victoriano Perez envía el reporte de atrasos) | H63: Diaria | J63: Cada día, Monica y su equipo vinculan todas las cargas a sus pedidos. Planificación envía un reporte diario de cargas atrasadas. | K63: A veces se crean cargas por mucha más cantidad que la del pedido y con fechas de entrega imposibles de cumplir. | L63: Al crear la carga, validar que la cantidad no supere lo pendiente del pedido y que la fecha sea la confirmada. El reporte de atrasos pasa a ser un KPI diario con su causa. | M63: Media | O63: Catálogo
A64: Ondupet | B64: Cartera | C64: 3.3 | D64: Cierre (saldado) de pedidos | E64: Informal | F64: Monica Gordillo y su equipo | H64: Sin pauta | J64: Comercial salda los pedidos. Da la sensación de que algunos, ya planificados, se saldan sin avisar a Planificación. | K64: Planificación puede seguir fabricando o reservando capacidad para pedidos que ya están cerrados. | L64: Saldado semanal con una regla común: Planificación propone qué pedidos saldar (completos o con un resto mínimo) y Comercial lo valida. Si se salda un pedido planificado, Planificación se entera en el momento. | M64: Media | O64: Catálogo
A65: Ondupet | B65: Cartera | C65: 3.4 | D65: Prioridad de pedidos en conflicto | E65: Informal | F65: Comercial (Monica Gordillo, Manuel Jesus Trinidad) y Victoriano Perez; decide Manuel Castro si no hay acuerdo | H65: Bajo demanda (por teléfono) | J65: Cuando hay varios pedidos comprometidos, Comercial (Monica y su equipo, o incluso Manuel Jesus) llama a Planificación para buscar soluciones. Si no se ponen de acuerdo, llaman a Manuel Castro (director de planta) para que decida. | K65: No hay reglas de prioridad: se resuelve caso a caso por teléfono y acaba en el director de planta. | L65: Reglas de prioridad acordadas (tipo de cliente, fecha comprometida, margen y stock de seguridad) que aplica Planificación consultando a Comercial y Programación. Si afecta a otras plantas, decide S&OP. Al director de planta solo se le informa. | M65: Media | O65: Catálogo
A66: Ondupet | B66: Necesidades | C66: 4.1 | D66: Ejecución y revisión del MRP | E66: Estándar propio | F66: Victoriano Perez (Planificación) y Barbara Ayuste (Compras) | G66: SAP · MRP y transacción de faltas de materia prima y auxiliares | H66: Semanal | J66: Cada semana, Planificación y Compras analizan juntos el MRP. Tienen preparada en SAP una transacción que muestra las faltas de materias primas y auxiliares. | K66: No se han detectado problemas. Falta confirmar cómo se tratan las excepciones del MRP y quién lanza los pedidos de las faltas. | L66: Tomarlo como base del estándar del grupo: revisión semanal Planificación–Compras con la transacción de faltas, incluyendo materias primas y auxiliares (4.4) en la misma revisión. | M66: Baja | O66: Catálogo
A67: Ondupet | B67: Necesidades | C67: 4.2 | D67: Propuesta de fabricación de producto terminado | E67: Estándar propio | F67: Victoriano Perez | G67: GIO · pantalla de propuesta de fabricación (por material y pedido) | H67: Diaria | J67: En GIO hay una pantalla que da, por material (y por pedido en los MTO), una propuesta de fabricación. Victoriano la consulta cada día y la corrige si ve desviaciones del accuracy o si Comercial le llama. | K67: Las correcciones son manuales y dependen de la persona; los cambios de Comercial llegan por teléfono y no queda registro del motivo. Los errores de la previsión (2.4) acaban corrigiéndose aquí. | L67: Corregir la propuesta solo con un motivo registrado y con reglas comunes. Los cambios de Comercial entran por la previsión o la cartera, no por llamada, y el KPI de accuracy indica dónde mirar. | M67: Media | O67: Catálogo
A68: Ondupet | B68: Necesidades | C68: 4.3 | D68: Necesidades de semielaborado | E68: Estándar propio | F68: Victoriano Perez | G68: GIO · pantalla de necesidades de semielaborado | H68: Diaria | J68: Una pantalla de GIO propone automáticamente las necesidades de semielaborado. Victoriano la revisa cada día con la misma lógica que el producto terminado. | K68: Igual que en 4.2: correcciones manuales sin registro que dependen de una sola persona. | L68: Mismas reglas de corrección que en 4.2. A medio plazo, que la revise el planificador de materiales para repartir la carga de Victoriano. | M68: Media | O68: Catálogo
A69: Ondupet | B69: Necesidades | C69: 4.4 | D69: Necesidades de materias primas y auxiliares | E69: Estándar propio | F69: Victoriano Perez y Barbara Ayuste (dentro de 4.1) | G69: SAP · transacción de faltas | H69: Semanal | J69: Se hace dentro de la revisión semanal del MRP (4.1). | L69: Fusionar 4.4 con 4.1 en el catálogo corporativo (lo propone el equipo en el E2E). | M69: Baja | N69: Del E2E: está duplicado, debería ir incluido en 4.1. | O69: Catálogo
A70: Ondupet | B70: Capacidad | C70: 5.1 | D70: Carga de capacidad y saturación por línea | E70: Sin revisar | O70: Catálogo
A71: Ondupet | B71: Capacidad | C71: 5.2 | D71: Balanceo entre líneas y plantas | E71: Sin revisar | O71: Catálogo
A72: Ondupet | B72: Capacidad | C72: 5.3 | D72: Saturación de almacenes | E72: Sin revisar | O72: Catálogo
A73: Ondupet | B73: Programación | C73: 6.1 | D73: Plan de producción semanal | E73: Sin revisar | O73: Catálogo
A74: Ondupet | B74: Programación | C74: 6.2 | D74: Secuenciación, ciclos y combinación | E74: Sin revisar | O74: Catálogo
A75: Ondupet | B75: Programación | C75: 6.3 | D75: Lanzamiento de órdenes a máquina | E75: Sin revisar | O75: Catálogo
A76: Ondupet | B76: Programación | C76: 6.4 | D76: Replanificación ante incidencias | E76: Sin revisar | O76: Catálogo
A77: Ondupet | B77: Programación | C77: 6.5 | D77: Cronograma de cambios | E77: Sin revisar | O77: Catálogo
...

Sheet Madurez
A1: Actividades alineadas con el estándar / actividades aplicables
A2: Se calcula desde la hoja Notas.
A4: Empresa | B4: Gobierno y S&OP | C4: Dato maestro | D4: Demanda | E4: Cartera | F4: Necesidades | G4: Capacidad | H4: Programación | I4: Entrega | J4: Control | K4: Intercompany | L4: Total
A5: Corporativo · Planificación | B5: =IFERROR(COUNTIFS(Notas!$A:$A,$A5,Notas!$B:$B,"Gobierno y S&OP",Notas!$E:$E,"Alineado con el estándar")/(COUNTIFS(Notas!$A:$A,$A5,Notas!$B:$B,"Gobierno y S&OP")-COUNTIFS(Notas!$A:$A,$A5,Notas!$B:$B,"Gobierno y S&OP",Notas!$E:$E,"No aplica")),0) -> 0 | C5: =IFERROR(COUNTIFS(Notas!$A:$A,$A5,Notas!$B:$B,"Dato maestro",Notas!$E:$E,"Alineado con el estándar")/(COUNTIFS(Notas!$A:$A,$A5,Notas!$B:$B,"Dato maestro")-COUNTIFS(Notas!$A:$A,$A5,Notas!$B:$B,"Dato maestro",Notas!$E:$E,"No aplica")),0) -> 0 | D5: =IFERROR(COUNTIFS(Notas!$A:$A,$A5,Notas!$B:$B,"Demanda",Notas!$E:$E,"Alineado con el estándar")/(COUNTIFS(Notas!$A:$A,$A5,Notas!$B:$B,"Demanda")-COUNTIFS(Notas!$A:$A,$A5,Notas!$B:$B,"Demanda",Notas!$E:$E,"No aplica")),0) -> 0 | E5: =IFERROR(COUNTIFS(Notas!$A:$A,$A5,Notas!$B:$B,"Cartera",Notas!$E:$E,"Alineado con el estándar")/(COUNTIFS(Notas!$A:$A,$A5,Notas!$B:$B,"Cartera")-COUNTIFS(Notas!$A:$A,$A5,Notas!$B:$B,"Cartera",Notas!$E:$E,"No aplica")),0) -> 0 | F5: =IFERROR(COUNTIFS(Notas!$A:$A,$A5,Notas!$B:$B,"Necesidades",Notas!$E:$E,"Alineado con el estándar")/(COUNTIFS(Notas!$A:$A,$A5,Notas!$B:$B,"Necesidades")-COUNTIFS(Notas!$A:$A,$A5,Notas!$B:$B,"Necesidades",Notas!$E:$E,"No aplica")),0) -> 0 | G5: =IFERROR(COUNTIFS(Notas!$A:$A,$A5,Notas!$B:$B,"Capacidad",Notas!$E:$E,"Alineado con el estándar")/(COUNTIFS(Notas!$A:$A,$A5,Notas!$B:$B,"Capacidad")-COUNTIFS(Notas!$A:$A,$A5,Notas!$B:$B,"Capacidad",Notas!$E:$E,"No aplica")),0) -> 0 | H5: =IFERROR(COUNTIFS(Notas!$A:$A,$A5,Notas!$B:$B,"Programación",Notas!$E:$E,"Alineado con el estándar")/(COUNTIFS(Notas!$A:$A,$A5,Notas!$B:$B,"Programación")-COUNTIFS(Notas!$A:$A,$A5,Notas!$B:$B,"Programación",Notas!$E:$E,"No aplica")),0) -> 0 | I5: =IFERROR(COUNTIFS(Notas!$A:$A,$A5,Notas!$B:$B,"Entrega",Notas!$E:$E,"Alineado con el estándar")/(COUNTIFS(Notas!$A:$A,$A5,Notas!$B:$B,"Entrega")-COUNTIFS(Notas!$A:$A,$A5,Notas!$B:$B,"Entrega",Notas!$E:$E,"No aplica")),0) -> 0 | J5: =IFERROR(COUNTIFS(Notas!$A:$A,$A5,Notas!$B:$B,"Control",Notas!$E:$E,"Alineado con el estándar")/(COUNTIFS(Notas!$A:$A,$A5,Notas!$B:$B,"Control")-COUNTIFS(Notas!$A:$A,$A5,Notas!$B:$B,"Control",Notas!$E:$E,"No aplica")),0) -> 0 | K5: =IFERROR(COUNTIFS(Notas!$A:$A,$A5,Notas!$B:$B,"Intercompany",Notas!$E:$E,"Alineado con el estándar")/(COUNTIFS(Notas!$A:$A,$A5,Notas!$B:$B,"Intercompany")-COUNTIFS(Notas!$A:$A,$A5,Notas!$B:$B,"Intercompany",Notas!$E:$E,"No aplica")),0) -> 0 | L5: =IFERROR(COUNTIFS(Notas!$A:$A,$A5,Notas!$E:$E,"Alineado con el estándar")/(COUNTIFS(Notas!$A:$A,$A5)-COUNTIFS(Notas!$A:$A,$A5,Notas!$E:$E,"No aplica")),0) -> 0
A6: Ondupet | B6: =IFERROR(COUNTIFS(Notas!$A:$A,$A6,Notas!$B:$B,"Gobierno y S&OP",Notas!$E:$E,"Alineado con el estándar")/(COUNTIFS(Notas!$A:$A,$A6,Notas!$B:$B,"Gobierno y S&OP")-COUNTIFS(Notas!$A:$A,$A6,Notas!$B:$B,"Gobierno y S&OP",Notas!$E:$E,"No aplica")),0) -> 0 | C6: =IFERROR(COUNTIFS(Notas!$A:$A,$A6,Notas!$B:$B,"Dato maestro",Notas!$E:$E,"Alineado con el estándar")/(COUNTIFS(Notas!$A:$A,$A6,Notas!$B:$B,"Dato maestro")-COUNTIFS(Notas!$A:$A,$A6,Notas!$B:$B,"Dato maestro",Notas!$E:$E,"No aplica")),0) -> 0 | D6: =IFERROR(COUNTIFS(Notas!$A:$A,$A6,Notas!$B:$B,"Demanda",Notas!$E:$E,"Alineado con el estándar")/(COUNTIFS(Notas!$A:$A,$A6,Notas!$B:$B,"Demanda")-COUNTIFS(Notas!$A:$A,$A6,Notas!$B:$B,"Demanda",Notas!$E:$E,"No aplica")),0) -> 0 | E6: =IFERROR(COUNTIFS(Notas!$A:$A,$A6,Notas!$B:$B,"Cartera",Notas!$E:$E,"Alineado con el estándar")/(COUNTIFS(Notas!$A:$A,$A6,Notas!$B:$B,"Cartera")-COUNTIFS(Notas!$A:$A,$A6,Notas!$B:$B,"Cartera",Notas!$E:$E,"No aplica")),0) -> 0 | F6: =IFERROR(COUNTIFS(Notas!$A:$A,$A6,Notas!$B:$B,"Necesidades",Notas!$E:$E,"Alineado con el estándar")/(COUNTIFS(Notas!$A:$A,$A6,Notas!$B:$B,"Necesidades")-COUNTIFS(Notas!$A:$A,$A6,Notas!$B:$B,"Necesidades",Notas!$E:$E,"No aplica")),0) -> 0 | G6: =IFERROR(COUNTIFS(Notas!$A:$A,$A6,Notas!$B:$B,"Capacidad",Notas!$E:$E,"Alineado con el estándar")/(COUNTIFS(Notas!$A:$A,$A6,Notas!$B:$B,"Capacidad")-COUNTIFS(Notas!$A:$A,$A6,Notas!$B:$B,"Capacidad",Notas!$E:$E,"No aplica")),0) -> 0 | H6: =IFERROR(COUNTIFS(Notas!$A:$A,$A6,Notas!$B:$B,"Programación",Notas!$E:$E,"Alineado con el estándar")/(COUNTIFS(Notas!$A:$A,$A6,Notas!$B:$B,"Programación")-COUNTIFS(Notas!$A:$A,$A6,Notas!$B:$B,"Programación",Notas!$E:$E,"No aplica")),0) -> 0 | I6: =IFERROR(COUNTIFS(Notas!$A:$A,$A6,Notas!$B:$B,"Entrega",Notas!$E:$E,"Alineado con el estándar")/(COUNTIFS(Notas!$A:$A,$A6,Notas!$B:$B,"Entrega")-COUNTIFS(Notas!$A:$A,$A6,Notas!$B:$B,"Entrega",Notas!$E:$E,"No aplica")),0) -> 0 | J6: =IFERROR(COUNTIFS(Notas!$A:$A,$A6,Notas!$B:$B,"Control",Notas!$E:$E,"Alineado con el estándar")/(COUNTIFS(Notas!$A:$A,$A6,Notas!$B:$B,"Control")-COUNTIFS(Notas!$A:$A,$A6,Notas!$B:$B,"Control",Notas!$E:$E,"No aplica")),0) -> 0 | K6: =IFERROR(COUNTIFS(Notas!$A:$A,$A6,Notas!$B:$B,"Intercompany",Notas!$E:$E,"Alineado con el estándar")/(COUNTIFS(Notas!$A:$A,$A6,Notas!$B:$B,"Intercompany")-COUNTIFS(Notas!$A:$A,$A6,Notas!$B:$B,"Intercompany",Notas!$E:$E,"No aplica")),0) -> 0 | L6: =IFERROR(COUNTIFS(Notas!$A:$A,$A6,Notas!$E:$E,"Alineado con el estándar")/(COUNTIFS(Notas!$A:$A,$A6)-COUNTIFS(Notas!$A:$A,$A6,Notas!$E:$E,"No aplica")),0) -> 0
A7: Ondupack Almendralejo | B7: =IFERROR(COUNTIFS(Notas!$A:$A,$A7,Notas!$B:$B,"Gobierno y S&OP",Notas!$E:$E,"Alineado con el estándar")/(COUNTIFS(Notas!$A:$A,$A7,Notas!$B:$B,"Gobierno y S&OP")-COUNTIFS(Notas!$A:$A,$A7,Notas!$B:$B,"Gobierno y S&OP",Notas!$E:$E,"No aplica")),0) -> 0 | C7: =IFERROR(COUNTIFS(Notas!$A:$A,$A7,Notas!$B:$B,"Dato maestro",Notas!$E:$E,"Alineado con el estándar")/(COUNTIFS(Notas!$A:$A,$A7,Notas!$B:$B,"Dato maestro")-COUNTIFS(Notas!$A:$A,$A7,Notas!$B:$B,"Dato maestro",Notas!$E:$E,"No aplica")),0) -> 0 | D7: =IFERROR(COUNTIFS(Notas!$A:$A,$A7,Notas!$B:$B,"Demanda",Notas!$E:$E,"Alineado con el estándar")/(COUNTIFS(Notas!$A:$A,$A7,Notas!$B:$B,"Demanda")-COUNTIFS(Notas!$A:$A,$A7,Notas!$B:$B,"Demanda",Notas!$E:$E,"No aplica")),0) -> 0 | E7: =IFERROR(COUNTIFS(Notas!$A:$A,$A7,Notas!$B:$B,"Cartera",Notas!$E:$E,"Alineado con el estándar")/(COUNTIFS(Notas!$A:$A,$A7,Notas!$B:$B,"Cartera")-COUNTIFS(Notas!$A:$A,$A7,Notas!$B:$B,"Cartera",Notas!$E:$E,"No aplica")),0) -> 0 | F7: =IFERROR(COUNTIFS(Notas!$A:$A,$A7,Notas!$B:$B,"Necesidades",Notas!$E:$E,"Alineado con el estándar")/(COUNTIFS(Notas!$A:$A,$A7,Notas!$B:$B,"Necesidades")-COUNTIFS(Notas!$A:$A,$A7,Notas!$B:$B,"Necesidades",Notas!$E:$E,"No aplica")),0) -> 0 | G7: =IFERROR(COUNTIFS(Notas!$A:$A,$A7,Notas!$B:$B,"Capacidad",Notas!$E:$E,"Alineado con el estándar")/(COUNTIFS(Notas!$A:$A,$A7,Notas!$B:$B,"Capacidad")-COUNTIFS(Notas!$A:$A,$A7,Notas!$B:$B,"Capacidad",Notas!$E:$E,"No aplica")),0) -> 0 | H7: =IFERROR(COUNTIFS(Notas!$A:$A,$A7,Notas!$B:$B,"Programación",Notas!$E:$E,"Alineado con el estándar")/(COUNTIFS(Notas!$A:$A,$A7,Notas!$B:$B,"Programación")-COUNTIFS(Notas!$A:$A,$A7,Notas!$B:$B,"Programación",Notas!$E:$E,"No aplica")),0) -> 0 | I7: =IFERROR(COUNTIFS(Notas!$A:$A,$A7,Notas!$B:$B,"Entrega",Notas!$E:$E,"Alineado con el estándar")/(COUNTIFS(Notas!$A:$A,$A7,Notas!$B:$B,"Entrega")-COUNTIFS(Notas!$A:$A,$A7,Notas!$B:$B,"Entrega",Notas!$E:$E,"No aplica")),0) -> 0 | J7: =IFERROR(COUNTIFS(Notas!$A:$A,$A7,Notas!$B:$B,"Control",Notas!$E:$E,"Alineado con el estándar")/(COUNTIFS(Notas!$A:$A,$A7,Notas!$B:$B,"Control")-COUNTIFS(Notas!$A:$A,$A7,Notas!$B:$B,"Control",Notas!$E:$E,"No aplica")),0) -> 0 | K7: =IFERROR(COUNTIFS(Notas!$A:$A,$A7,Notas!$B:$B,"Intercompany",Notas!$E:$E,"Alineado con el estándar")/(COUNTIFS(Notas!$A:$A,$A7,Notas!$B:$B,"Intercompany")-COUNTIFS(Notas!$A:$A,$A7,Notas!$B:$B,"Intercompany",Notas!$E:$E,"No aplica")),0) -> 0 | L7: =IFERROR(COUNTIFS(Notas!$A:$A,$A7,Notas!$E:$E,"Alineado con el estándar")/(COUNTIFS(Notas!$A:$A,$A7)-COUNTIFS(Notas!$A:$A,$A7,Notas!$E:$E,"No aplica")),0) -> 0
A8: Ondupack Navalmoral | B8: =IFERROR(COUNTIFS(Notas!$A:$A,$A8,Notas!$B:$B,"Gobierno y S&OP",Notas!$E:$E,"Alineado con el estándar")/(COUNTIFS(Notas!$A:$A,$A8,Notas!$B:$B,"Gobierno y S&OP")-COUNTIFS(Notas!$A:$A,$A8,Notas!$B:$B,"Gobierno y S&OP",Notas!$E:$E,"No aplica")),0) -> 0 | C8: =IFERROR(COUNTIFS(Notas!$A:$A,$A8,Notas!$B:$B,"Dato maestro",Notas!$E:$E,"Alineado con el estándar")/(COUNTIFS(Notas!$A:$A,$A8,Notas!$B:$B,"Dato maestro")-COUNTIFS(Notas!$A:$A,$A8,Notas!$B:$B,"Dato maestro",Notas!$E:$E,"No aplica")),0) -> 0 | D8: =IFERROR(COUNTIFS(Notas!$A:$A,$A8,Notas!$B:$B,"Demanda",Notas!$E:$E,"Alineado con el estándar")/(COUNTIFS(Notas!$A:$A,$A8,Notas!$B:$B,"Demanda")-COUNTIFS(Notas!$A:$A,$A8,Notas!$B:$B,"Demanda",Notas!$E:$E,"No aplica")),0) -> 0 | E8: =IFERROR(COUNTIFS(Notas!$A:$A,$A8,Notas!$B:$B,"Cartera",Notas!$E:$E,"Alineado con el estándar")/(COUNTIFS(Notas!$A:$A,$A8,Notas!$B:$B,"Cartera")-COUNTIFS(Notas!$A:$A,$A8,Notas!$B:$B,"Cartera",Notas!$E:$E,"No aplica")),0) -> 0 | F8: =IFERROR(COUNTIFS(Notas!$A:$A,$A8,Notas!$B:$B,"Necesidades",Notas!$E:$E,"Alineado con el estándar")/(COUNTIFS(Notas!$A:$A,$A8,Notas!$B:$B,"Necesidades")-COUNTIFS(Notas!$A:$A,$A8,Notas!$B:$B,"Necesidades",Notas!$E:$E,"No aplica")),0) -> 0 | G8: =IFERROR(COUNTIFS(Notas!$A:$A,$A8,Notas!$B:$B,"Capacidad",Notas!$E:$E,"Alineado con el estándar")/(COUNTIFS(Notas!$A:$A,$A8,Notas!$B:$B,"Capacidad")-COUNTIFS(Notas!$A:$A,$A8,Notas!$B:$B,"Capacidad",Notas!$E:$E,"No aplica")),0) -> 0 | H8: =IFERROR(COUNTIFS(Notas!$A:$A,$A8,Notas!$B:$B,"Programación",Notas!$E:$E,"Alineado con el estándar")/(COUNTIFS(Notas!$A:$A,$A8,Notas!$B:$B,"Programación")-COUNTIFS(Notas!$A:$A,$A8,Notas!$B:$B,"Programación",Notas!$E:$E,"No aplica")),0) -> 0 | I8: =IFERROR(COUNTIFS(Notas!$A:$A,$A8,Notas!$B:$B,"Entrega",Notas!$E:$E,"Alineado con el estándar")/(COUNTIFS(Notas!$A:$A,$A8,Notas!$B:$B,"Entrega")-COUNTIFS(Notas!$A:$A,$A8,Notas!$B:$B,"Entrega",Notas!$E:$E,"No aplica")),0) -> 0 | J8: =IFERROR(COUNTIFS(Notas!$A:$A,$A8,Notas!$B:$B,"Control",Notas!$E:$E,"Alineado con el estándar")/(COUNTIFS(Notas!$A:$A,$A8,Notas!$B:$B,"Control")-COUNTIFS(Notas!$A:$A,$A8,Notas!$B:$B,"Control",Notas!$E:$E,"No aplica")),0) -> 0 | K8: =IFERROR(COUNTIFS(Notas!$A:$A,$A8,Notas!$B:$B,"Intercompany",Notas!$E:$E,"Alineado con el estándar")/(COUNTIFS(Notas!$A:$A,$A8,Notas!$B:$B,"Intercompany")-COUNTIFS(Notas!$A:$A,$A8,Notas!$B:$B,"Intercompany",Notas!$E:$E,"No aplica")),0) -> 0 | L8: =IFERROR(COUNTIFS(Notas!$A:$A,$A8,Notas!$E:$E,"Alineado con el estándar")/(COUNTIFS(Notas!$A:$A,$A8)-COUNTIFS(Notas!$A:$A,$A8,Notas!$E:$E,"No aplica")),0) -> 0
A9: MGT | B9: =IFERROR(COUNTIFS(Notas!$A:$A,$A9,Notas!$B:$B,"Gobierno y S&OP",Notas!$E:$E,"Alineado con el estándar")/(COUNTIFS(Notas!$A:$A,$A9,Notas!$B:$B,"Gobierno y S&OP")-COUNTIFS(Notas!$A:$A,$A9,Notas!$B:$B,"Gobierno y S&OP",Notas!$E:$E,"No aplica")),0) -> 0 | C9: =IFERROR(COUNTIFS(Notas!$A:$A,$A9,Notas!$B:$B,"Dato maestro",Notas!$E:$E,"Alineado con el estándar")/(COUNTIFS(Notas!$A:$A,$A9,Notas!$B:$B,"Dato maestro")-COUNTIFS(Notas!$A:$A,$A9,Notas!$B:$B,"Dato maestro",Notas!$E:$E,"No aplica")),0) -> 0 | D9: =IFERROR(COUNTIFS(Notas!$A:$A,$A9,Notas!$B:$B,"Demanda",Notas!$E:$E,"Alineado con el estándar")/(COUNTIFS(Notas!$A:$A,$A9,Notas!$B:$B,"Demanda")-COUNTIFS(Notas!$A:$A,$A9,Notas!$B:$B,"Demanda",Notas!$E:$E,"No aplica")),0) -> 0 | E9: =IFERROR(COUNTIFS(Notas!$A:$A,$A9,Notas!$B:$B,"Cartera",Notas!$E:$E,"Alineado con el estándar")/(COUNTIFS(Notas!$A:$A,$A9,Notas!$B:$B,"Cartera")-COUNTIFS(Notas!$A:$A,$A9,Notas!$B:$B,"Cartera",Notas!$E:$E,"No aplica")),0) -> 0 | F9: =IFERROR(COUNTIFS(Notas!$A:$A,$A9,Notas!$B:$B,"Necesidades",Notas!$E:$E,"Alineado con el estándar")/(COUNTIFS(Notas!$A:$A,$A9,Notas!$B:$B,"Necesidades")-COUNTIFS(Notas!$A:$A,$A9,Notas!$B:$B,"Necesidades",Notas!$E:$E,"No aplica")),0) -> 0 | G9: =IFERROR(COUNTIFS(Notas!$A:$A,$A9,Notas!$B:$B,"Capacidad",Notas!$E:$E,"Alineado con el estándar")/(COUNTIFS(Notas!$A:$A,$A9,Notas!$B:$B,"Capacidad")-COUNTIFS(Notas!$A:$A,$A9,Notas!$B:$B,"Capacidad",Notas!$E:$E,"No aplica")),0) -> 0 | H9: =IFERROR(COUNTIFS(Notas!$A:$A,$A9,Notas!$B:$B,"Programación",Notas!$E:$E,"Alineado con el estándar")/(COUNTIFS(Notas!$A:$A,$A9,Notas!$B:$B,"Programación")-COUNTIFS(Notas!$A:$A,$A9,Notas!$B:$B,"Programación",Notas!$E:$E,"No aplica")),0) -> 0 | I9: =IFERROR(COUNTIFS(Notas!$A:$A,$A9,Notas!$B:$B,"Entrega",Notas!$E:$E,"Alineado con el estándar")/(COUNTIFS(Notas!$A:$A,$A9,Notas!$B:$B,"Entrega")-COUNTIFS(Notas!$A:$A,$A9,Notas!$B:$B,"Entrega",Notas!$E:$E,"No aplica")),0) -> 0 | J9: =IFERROR(COUNTIFS(Notas!$A:$A,$A9,Notas!$B:$B,"Control",Notas!$E:$E,"Alineado con el estándar")/(COUNTIFS(Notas!$A:$A,$A9,Notas!$B:$B,"Control")-COUNTIFS(Notas!$A:$A,$A9,Notas!$B:$B,"Control",Notas!$E:$E,"No aplica")),0) -> 0 | K9: =IFERROR(COUNTIFS(Notas!$A:$A,$A9,Notas!$B:$B,"Intercompany",Notas!$E:$E,"Alineado con el estándar")/(COUNTIFS(Notas!$A:$A,$A9,Notas!$B:$B,"Intercompany")-COUNTIFS(Notas!$A:$A,$A9,Notas!$B:$B,"Intercompany",Notas!$E:$E,"No aplica")),0) -> 0 | L9: =IFERROR(COUNTIFS(Notas!$A:$A,$A9,Notas!$E:$E,"Alineado con el estándar")/(COUNTIFS(Notas!$A:$A,$A9)-COUNTIFS(Notas!$A:$A,$A9,Notas!$E:$E,"No aplica")),0) -> 0
A10: PDA | B10: =IFERROR(COUNTIFS(Notas!$A:$A,$A10,Notas!$B:$B,"Gobierno y S&OP",Notas!$E:$E,"Alineado con el estándar")/(COUNTIFS(Notas!$A:$A,$A10,Notas!$B:$B,"Gobierno y S&OP")-COUNTIFS(Notas!$A:$A,$A10,Notas!$B:$B,"Gobierno y S&OP",Notas!$E:$E,"No aplica")),0) -> 0 | C10: =IFERROR(COUNTIFS(Notas!$A:$A,$A10,Notas!$B:$B,"Dato maestro",Notas!$E:$E,"Alineado con el estándar")/(COUNTIFS(Notas!$A:$A,$A10,Notas!$B:$B,"Dato maestro")-COUNTIFS(Notas!$A:$A,$A10,Notas!$B:$B,"Dato maestro",Notas!$E:$E,"No aplica")),0) -> 0 | D10: =IFERROR(COUNTIFS(Notas!$A:$A,$A10,Notas!$B:$B,"Demanda",Notas!$E:$E,"Alineado con el estándar")/(COUNTIFS(Notas!$A:$A,$A10,Notas!$B:$B,"Demanda")-COUNTIFS(Notas!$A:$A,$A10,Notas!$B:$B,"Demanda",Notas!$E:$E,"No aplica")),0) -> 0 | E10: =IFERROR(COUNTIFS(Notas!$A:$A,$A10,Notas!$B:$B,"Cartera",Notas!$E:$E,"Alineado con el estándar")/(COUNTIFS(Notas!$A:$A,$A10,Notas!$B:$B,"Cartera")-COUNTIFS(Notas!$A:$A,$A10,Notas!$B:$B,"Cartera",Notas!$E:$E,"No aplica")),0) -> 0 | F10: =IFERROR(COUNTIFS(Notas!$A:$A,$A10,Notas!$B:$B,"Necesidades",Notas!$E:$E,"Alineado con el estándar")/(COUNTIFS(Notas!$A:$A,$A10,Notas!$B:$B,"Necesidades")-COUNTIFS(Notas!$A:$A,$A10,Notas!$B:$B,"Necesidades",Notas!$E:$E,"No aplica")),0) -> 0 | G10: =IFERROR(COUNTIFS(Notas!$A:$A,$A10,Notas!$B:$B,"Capacidad",Notas!$E:$E,"Alineado con el estándar")/(COUNTIFS(Notas!$A:$A,$A10,Notas!$B:$B,"Capacidad")-COUNTIFS(Notas!$A:$A,$A10,Notas!$B:$B,"Capacidad",Notas!$E:$E,"No aplica")),0) -> 0 | H10: =IFERROR(COUNTIFS(Notas!$A:$A,$A10,Notas!$B:$B,"Programación",Notas!$E:$E,"Alineado con el estándar")/(COUNTIFS(Notas!$A:$A,$A10,Notas!$B:$B,"Programación")-COUNTIFS(Notas!$A:$A,$A10,Notas!$B:$B,"Programación",Notas!$E:$E,"No aplica")),0) -> 0 | I10: =IFERROR(COUNTIFS(Notas!$A:$A,$A10,Notas!$B:$B,"Entrega",Notas!$E:$E,"Alineado con el estándar")/(COUNTIFS(Notas!$A:$A,$A10,Notas!$B:$B,"Entrega")-COUNTIFS(Notas!$A:$A,$A10,Notas!$B:$B,"Entrega",Notas!$E:$E,"No aplica")),0) -> 0 | J10: =IFERROR(COUNTIFS(Notas!$A:$A,$A10,Notas!$B:$B,"Control",Notas!$E:$E,"Alineado con el estándar")/(COUNTIFS(Notas!$A:$A,$A10,Notas!$B:$B,"Control")-COUNTIFS(Notas!$A:$A,$A10,Notas!$B:$B,"Control",Notas!$E:$E,"No aplica")),0) -> 0 | K10: =IFERROR(COUNTIFS(Notas!$A:$A,$A10,Notas!$B:$B,"Intercompany",Notas!$E:$E,"Alineado con el estándar")/(COUNTIFS(Notas!$A:$A,$A10,Notas!$B:$B,"Intercompany")-COUNTIFS(Notas!$A:$A,$A10,Notas!$B:$B,"Intercompany",Notas!$E:$E,"No aplica")),0) -> 0 | L10: =IFERROR(COUNTIFS(Notas!$A:$A,$A10,Notas!$E:$E,"Alineado con el estándar")/(COUNTIFS(Notas!$A:$A,$A10)-COUNTIFS(Notas!$A:$A,$A10,Notas!$E:$E,"No aplica")),0) -> 0
A11: Papresa | B11: =IFERROR(COUNTIFS(Notas!$A:$A,$A11,Notas!$B:$B,"Gobierno y S&OP",Notas!$E:$E,"Alineado con el estándar")/(COUNTIFS(Notas!$A:$A,$A11,Notas!$B:$B,"Gobierno y S&OP")-COUNTIFS(Notas!$A:$A,$A11,Notas!$B:$B,"Gobierno y S&OP",Notas!$E:$E,"No aplica")),0) -> 0 | C11: =IFERROR(COUNTIFS(Notas!$A:$A,$A11,Notas!$B:$B,"Dato maestro",Notas!$E:$E,"Alineado con el estándar")/(COUNTIFS(Notas!$A:$A,$A11,Notas!$B:$B,"Dato maestro")-COUNTIFS(Notas!$A:$A,$A11,Notas!$B:$B,"Dato maestro",Notas!$E:$E,"No aplica")),0) -> 0 | D11: =IFERROR(COUNTIFS(Notas!$A:$A,$A11,Notas!$B:$B,"Demanda",Notas!$E:$E,"Alineado con el estándar")/(COUNTIFS(Notas!$A:$A,$A11,Notas!$B:$B,"Demanda")-COUNTIFS(Notas!$A:$A,$A11,Notas!$B:$B,"Demanda",Notas!$E:$E,"No aplica")),0) -> 0 | E11: =IFERROR(COUNTIFS(Notas!$A:$A,$A11,Notas!$B:$B,"Cartera",Notas!$E:$E,"Alineado con el estándar")/(COUNTIFS(Notas!$A:$A,$A11,Notas!$B:$B,"Cartera")-COUNTIFS(Notas!$A:$A,$A11,Notas!$B:$B,"Cartera",Notas!$E:$E,"No aplica")),0) -> 0 | F11: =IFERROR(COUNTIFS(Notas!$A:$A,$A11,Notas!$B:$B,"Necesidades",Notas!$E:$E,"Alineado con el estándar")/(COUNTIFS(Notas!$A:$A,$A11,Notas!$B:$B,"Necesidades")-COUNTIFS(Notas!$A:$A,$A11,Notas!$B:$B,"Necesidades",Notas!$E:$E,"No aplica")),0) -> 0 | G11: =IFERROR(COUNTIFS(Notas!$A:$A,$A11,Notas!$B:$B,"Capacidad",Notas!$E:$E,"Alineado con el estándar")/(COUNTIFS(Notas!$A:$A,$A11,Notas!$B:$B,"Capacidad")-COUNTIFS(Notas!$A:$A,$A11,Notas!$B:$B,"Capacidad",Notas!$E:$E,"No aplica")),0) -> 0 | H11: =IFERROR(COUNTIFS(Notas!$A:$A,$A11,Notas!$B:$B,"Programación",Notas!$E:$E,"Alineado con el estándar")/(COUNTIFS(Notas!$A:$A,$A11,Notas!$B:$B,"Programación")-COUNTIFS(Notas!$A:$A,$A11,Notas!$B:$B,"Programación",Notas!$E:$E,"No aplica")),0) -> 0 | I11: =IFERROR(COUNTIFS(Notas!$A:$A,$A11,Notas!$B:$B,"Entrega",Notas!$E:$E,"Alineado con el estándar")/(COUNTIFS(Notas!$A:$A,$A11,Notas!$B:$B,"Entrega")-COUNTIFS(Notas!$A:$A,$A11,Notas!$B:$B,"Entrega",Notas!$E:$E,"No aplica")),0) -> 0 | J11: =IFERROR(COUNTIFS(Notas!$A:$A,$A11,Notas!$B:$B,"Control",Notas!$E:$E,"Alineado con el estándar")/(COUNTIFS(Notas!$A:$A,$A11,Notas!$B:$B,"Control")-COUNTIFS(Notas!$A:$A,$A11,Notas!$B:$B,"Control",Notas!$E:$E,"No aplica")),0) -> 0 | K11: =IFERROR(COUNTIFS(Notas!$A:$A,$A11,Notas!$B:$B,"Intercompany",Notas!$E:$E,"Alineado con el estándar")/(COUNTIFS(Notas!$A:$A,$A11,Notas!$B:$B,"Intercompany")-COUNTIFS(Notas!$A:$A,$A11,Notas!$B:$B,"Intercompany",Notas!$E:$E,"No aplica")),0) -> 0 | L11: =IFERROR(COUNTIFS(Notas!$A:$A,$A11,Notas!$E:$E,"Alineado con el estándar")/(COUNTIFS(Notas!$A:$A,$A11)-COUNTIFS(Notas!$A:$A,$A11,Notas!$E:$E,"No aplica")),0) -> 0

Sheet Procesos
A1: Proceso | B1: ID | C1: Actividad | D1: Descripción | E1: Frecuencia estándar | F1: Decide (A) | G1: Ejecuta (R)
A2: Gobierno y S&OP | B2: G.1 | C2: Modelo de procesos y manual de planificación | D2: Definir, documentar y mantener cómo se ejecuta cada actividad en todas las plantas. | E2: Continua | F2: Director/a de Planificación | G2: Responsable de procesos (Functional Lead)
A3: Gobierno y S&OP | B3: G.2 | C3: Políticas de planificación | D3: MTS/MTO, stock de seguridad, horizonte congelado, prioridades, lotes, mínimos y máximos. | E3: Trimestral | F3: Director/a de Planificación | G3: Responsable de procesos (Functional Lead)
A4: Gobierno y S&OP | B4: G.3 | C4: S&OP mensual del grupo | D4: Revisión de demanda, de suministro y reunión ejecutiva para decidir capacidad y prioridades. | E4: Mensual | F4: Director/a de Planificación | G4: Coordinador/a de S&OP e intercompany
A5: Gobierno y S&OP | B5: G.4 | C5: Objetivos y revisión de KPIs | D5: Fijar objetivos por planta y revisar el cuadro de mando común. | E5: Mensual | F5: Director/a de Planificación | G5: Responsable de procesos (Functional Lead)
A6: Gobierno y S&OP | B6: G.5 | C6: Roles, personas, suplencias y formación | D6: Asignar cada rol con nombre y apellidos, con titular y suplente, y su plan de formación. | E6: Trimestral | F6: Director/a de Planificación | G6: Responsable de procesos (Functional Lead)
A7: Gobierno y S&OP | B7: G.6 | C7: Gestión de cambios y prioridad de desarrollos | D7: Canal único de peticiones, priorización y paso a producción de mejoras. | E7: Semanal | F7: Director/a de Planificación | G7: Responsable de procesos (Functional Lead), Sistemas de planificación (Technical Lead y desarrollo)
A8: Dato maestro | B8: 1.1 | C8: Datos de planificación del material | D8: Altas y mantenimiento de los datos que usa la planificación (unidades, rutas, máquinas por defecto). | E8: Diaria | F8: Responsable de dato maestro | G8: Responsable de dato maestro
A9: Dato maestro | B9: 1.2 | C9: Segmentación ABC/XYZ y estrategia MTS/MTO | D9: Clasificar materiales y asignar su estrategia de planificación con criterio común. | E9: Trimestral | F9: Responsable de procesos (Functional Lead) | G9: Responsable de dato maestro
A10: Dato maestro | B10: 1.3 | C10: Velocidades, tiempos de cambio y rutas | D10: Mantener los estándares de máquina a partir de los datos reales registrados. | E10: Mensual | F10: Responsable de dato maestro | G10: Responsable de dato maestro, Programador/a de producción
A11: Dato maestro | B11: 1.4 | C11: Calendario de turnos, días y paradas | D11: Turnos activos, días festivos y paradas de mantenimiento por máquina. | E11: Semanal | F11: Responsable de planificación de planta | G11: Programador/a de producción
A12: Dato maestro | B12: 1.5 | C12: Auditoría de calidad del dato | D12: Detectar duplicados, datos incompletos e incoherencias y corregirlos. | E12: Mensual | F12: Responsable de procesos (Functional Lead) | G12: Responsable de dato maestro
... A45: Intercompany | B45: I.5 | C45: Control y cierre de pedidos intercompany | D45: Apertura y cierre controlado de pedidos entre plantas. | E45: Semanal | F45: Coordinador/a de S&OP e intercompany | G45: Planificador/a de materiales

Sheet Flujos
A1: Empresa | B1: Vista | C1: Proceso | D1: Nº | E1: Tipo | F1: Paso | G1: Responsable | H1: Sistema / herramienta | I1: Actividad | J1: Punto de dolor | K1: Siguiente | L1: Notas
A2: Ondupet | B2: As-is | C2: Dato maestro | D2: 1 | E2: Inicio / fin | F2: Material nuevo | K2: → 2
A3: Ondupet | B3: As-is | C3: Dato maestro | D3: 2 | E3: Tarea | F3: Comercial detecta que hace falta un material nuevo | G3: Monica Gordillo | I3: 1.1 | K3: → 3
A4: Ondupet | B4: As-is | C4: Dato maestro | D4: 3 | E4: Tarea | F4: Consulta a Calidad las características técnicas | G4: Monica Gordillo · Calidad | K4: → 4
A5: Ondupet | B5: As-is | C5: Dato maestro | D5: 4 | E5: Tarea | F5: Alta del material: molde, velocidad, tiempos de cambio y ruta por defecto | G5: Monica Gordillo | H5: GIO | I5: 1.1 | J5: Sí | K5: → 5 | L5: No se consulta a Planificación la estrategia (MTS/MTO, ABC) ni la ruta.
A6: Ondupet | B6: As-is | C6: Dato maestro | D6: 5 | E6: Tarea | F6: Planificación planifica con el dato tal cual llega | G6: Victoriano Perez | H6: GIO | K6: → 6
A7: Ondupet | B7: As-is | C7: Dato maestro | D7: 6 | E7: Decisión | F7: ¿Aparece un duplicado? | K7: → 8 (Sí); → 7 (No)
A8: Ondupet | B8: As-is | C8: Dato maestro | D8: 7 | E8: Inicio / fin | F8: Material en uso
A9: Ondupet | B9: As-is | C9: Dato maestro | D9: 8 | E9: Tarea | F9: Corrección puntual con el campo «material reemplazante» | G9: Monica Gordillo y equipo | H9: GIO | I9: 1.5 | J9: Sí | K9: → 7 | L9: No hay auditoría ni criterio de qué define un material: los duplicados aparecen por casualidad.
A10: Ondupet | B10: As-is | C10: Dato maestro | D10: 9 | E10: Nota | F10: ¿Se consulta a Producción y Mantenimiento la ruta por defecto? Duda abierta. | K10: → 4
A11: Ondupet | B11: As-is | C11: Dato maestro | D11: 10 | E11: Nota | F11: Nadie revisa ABC ni estrategias (1.2) ni reequilibra las rutas con la carga del mes (1.3). | K11: → 5
A12: Ondupet | B12: As-is | C12: Demanda | D12: 1 | E12: Inicio / fin | F12: Inicio de mes | K12: → 2
A13: Ondupet | B13: As-is | C13: Demanda | D13: 2 | E13: Tarea | F13: Comercial carga la previsión de cada material: mes en curso + 3 | G13: Manuel Jesus Trinidad | I13: 2.1 | J13: Sí | K13: → 3 | L13: No hay día límite para cerrar la previsión.
A14: Ondupet | B14: As-is | C14: Demanda | D14: 3 | E14: Tarea | F14: Planificación calcula qué fabricar con la previsión, el stock y las órdenes lanzadas | G14: Victoriano Perez | K14: → 4
A15: Ondupet | B15: As-is | C15: Demanda | D15: 4 | E15: Tarea | F15: Genera los temporales para reservar tiempo de cada familia en el ciclo | G15: Victoriano Perez | I15: 2.5 | J15: Sí | K15: → 5 | L15: No se revisan con Comercial.
A16: Ondupet | B16: As-is | C16: Demanda | D16: 5 | E16: Tarea | F16: Comercial cambia la previsión del mes en curso sin consultar a Planificación | G16: Manuel Jesus Trinidad | I16: 2.1 | J16: Sí | K16: → 6 | L16: A veces con el material ya fabricado.
A17: Ondupet | B17: As-is | C17: Demanda | D17: 6 | E17: Tarea | F17: Registro de agotados irregular: épocas con muchos y meses sin ninguno | G17: Monica Gordillo y equipo | I17: 2.3 | J17: Sí | K17: → 7
A18: Ondupet | B18: As-is | C18: Demanda | D18: 7 | E18: Tarea | F18: Reunión mensual de accuracy | G18: Manuel Jesus Trinidad · Victoriano Perez | I18: 2.4 | J18: Sí | K18: → 8 | L18: Comercial no se implica y Planificación no la impulsa.
A19: Ondupet | B19: As-is | C19: Demanda | D19: 8 | E19: Inicio / fin | F19: Fin de mes sin acciones | J19: Sí
A20: Ondupet | B20: As-is | C20: Demanda | D20: 9 | E20: Nota | F20: No hay consenso con Comercial (2.2): Planificación fabrica lo que diga la previsión. | K20: → 3
A21: Ondupet | B21: As-is | C21: Cartera | D21: 1 | E21: Inicio / fin | F21: Inicio del día | K21: → 2; → 3
A22: Ondupet | B22: As-is | C22: Cartera | D22: 2 | E22: Tarea | F22: Comercial revisa cartera, stock y cargas | G22: Monica Gordillo | H22: SAP | I22: 3.1 | K22: → 4
A23: Ondupet | B23: As-is | C23: Cartera | D23: 3 | E23: Tarea | F23: Planificación revisa por su cuenta cartera, stock y cargas | G23: Victoriano Perez | H23: GIO | I23: 3.1 | K23: → 4
A24: Ondupet | B24: As-is | C24: Cartera | D24: 4 | E24: Tarea | F24: Puesta en común en la reunión de producción | G24: Comercial · Planificación · Producción | I24: 3.1 | K24: → 5
A25: Ondupet | B25: As-is | C25: Cartera | D25: 5 | E25: Tarea | F25: Fechas sin consenso: se mantiene la del cliente aunque no se llegue | G25: Comercial | I25: 3.1 | J25: Sí | K25: → 6 | L25: El pedido tiene dos fechas (la del cliente y otra para medir retrasos), pero no se usan.
A26: Ondupet | B26: As-is | C26: Cartera | D26: 6 | E26: Tarea | F26: Comercial vincula a diario las cargas a los pedidos | G26: Monica Gordillo y equipo | H26: SAP | I26: 3.2 | J26: Sí | K26: → 7 | L26: A veces se crean cargas por mucha más cantidad que el pedido y con fechas imposibles.
A27: Ondupet | B27: As-is | C27: Cartera | D27: 7 | E27: Tarea | F27: Planificación envía el reporte diario de cargas atrasadas | G27: Victoriano Perez | I27: 3.2 | K27: → 8
A28: Ondupet | B28: As-is | C28: Cartera | D28: 8 | E28: Decisión | F28: ¿Pedidos en conflicto? | K28: → 9 (No); → 10 (Sí)
A29: Ondupet | B29: As-is | C29: Cartera | D29: 9 | E29: Inicio / fin | F29: Fin del día
A30: Ondupet | B30: As-is | C30: Cartera | D30: 10 | E30: Tarea | F30: Comercial llama a Planificación para buscar una solución | G30: Monica Gordillo · Manuel Jesus Trinidad | I30: 3.4 | K30: → 11
A31: Ondupet | B31: As-is | C31: Cartera | D31: 11 | E31: Decisión | F31: ¿Hay acuerdo? | K31: → 12 (Sí); → 13 (No)
A32: Ondupet | B32: As-is | C32: Cartera | D32: 12 | E32: Inicio / fin | F32: Prioridad resuelta
A33: Ondupet | B33: As-is | C33: Cartera | D33: 13 | E33: Tarea | F33: Decide el director de planta | G33: Manuel Castro | I33: 3.4 | J33: Sí | K33: → 12 | L33: No hay reglas de prioridad.
A34: Ondupet | B34: As-is | C34: Cartera | D34: 14 | E34: Tarea | F34: Comercial salda pedidos, algunos ya planificados, sin avisar a Planificación | G34: Monica Gordillo y equipo | H34: SAP | I34: 3.3 | J34: Sí
A35: Ondupet | B35: As-is | C35: Necesidades | D35: 1 | E35: Inicio / fin | F35: Inicio de semana | K35: → 2
A36: Ondupet | B36: As-is | C36: Necesidades | D36: 2 | E36: Tarea | F36: Ejecución del MRP | H36: SAP | I36: 4.1 | K36: → 3
A37: Ondupet | B37: As-is | C37: Necesidades | D37: 3 | E37: Tarea | F37: Planificación y Compras revisan el MRP y las faltas de MP y auxiliares | G37: Victoriano Perez · Barbara Ayuste | H37: SAP | I37: 4.1 | K37: → 4
A38: Ondupet | B38: As-is | C38: Necesidades | D38: 4 | E38: Tarea | F38: Compras gestiona las necesidades de materias primas y auxiliares | G38: Barbara Ayuste | H38: SAP | I38: 4.4
A39: Ondupet | B39: As-is | C39: Necesidades | D39: 5 | E39: Inicio / fin | F39: Cada día | K39: → 6
A40: Ondupet | B40: As-is | C40: Necesidades | D40: 6 | E40: Tarea | F40: GIO propone la fabricación de producto terminado (por material y pedido en MTO) | H40: GIO | I40: 4.2 | K40: → 7
...

Sheet RACI
A1: Matriz RACI
D2: CORPORATIVO | H2: PLANTA
A3: Proceso | B3: ID | C3: Actividad | D3: Dir. Planificación | E3: Resp. procesos | F3: S&OP / Intercompany | G3: Sistemas | H3: Dir. planta | I3: Dato maestro | J3: Resp. planif. planta | K3: Demanda y cartera | L3: Programación | M3: Producción | N3: Producción | O3: Compras | P3: Materiales | Q3: Comercial | R3: Logística | S3: Revisión
A4: Gobierno y S&OP | B4: G.1 | C4: Modelo de procesos y manual de planificación | D4: A | E4: R | G4: C | H4: I | J4: C | S4: =IF(COUNTIF(D4:R4,"A")+COUNTIF(D4:R4,"A/R")<>1,"Revisar A",IF(COUNTIF(D4:R4,"R")+COUNTIF(D4:R4,"A/R")=0,"Falta R","OK")) -> OK
A5: Gobierno y S&OP | B5: G.2 | C5: Políticas de planificación | D5: A | E5: R | F5: C | H5: C | J5: C | K5: I | L5: I | P5: I | Q5: C | S5: =IF(COUNTIF(D5:R5,"A")+COUNTIF(D5:R5,"A/R")<>1,"Revisar A",IF(COUNTIF(D5:R5,"R")+COUNTIF(D5:R5,"A/R")=0,"Falta R","OK")) -> OK
A6: Gobierno y S&OP | B6: G.3 | C6: S&OP mensual del grupo | D6: A | E6: I | F6: R | H6: C | J6: C | O6: C | Q6: C | S6: =IF(COUNTIF(D6:R6,"A")+COUNTIF(D6:R6,"A/R")<>1,"Revisar A",IF(COUNTIF(D6:R6,"R")+COUNTIF(D6:R6,"A/R")=0,"Falta R","OK")) -> OK
A7: Gobierno y S&OP | B7: G.4 | C7: Objetivos y revisión de KPIs | D7: A | E7: R | H7: C | J7: C | K7: I | L7: I | P7: I | S7: =IF(COUNTIF(D7:R7,"A")+COUNTIF(D7:R7,"A/R")<>1,"Revisar A",IF(COUNTIF(D7:R7,"R")+COUNTIF(D7:R7,"A/R")=0,"Falta R","OK")) -> OK
A8: Gobierno y S&OP | B8: G.5 | C8: Roles, personas, suplencias y formación | D8: A | E8: R | H8: C | J8: C | K8: I | L8: I | P8: I | S8: =IF(COUNTIF(D8:R8,"A")+COUNTIF(D8:R8,"A/R")<>1,"Revisar A",IF(COUNTIF(D8:R8,"R")+COUNTIF(D8:R8,"A/R")=0,"Falta R","OK")) -> OK
A9: Gobierno y S&OP | B9: G.6 | C9: Gestión de cambios y prioridad de desarrollos | D9: A | E9: R | G9: R | H9: I | J9: C | S9: =IF(COUNTIF(D9:R9,"A")+COUNTIF(D9:R9,"A/R")<>1,"Revisar A",IF(COUNTIF(D9:R9,"R")+COUNTIF(D9:R9,"A/R")=0,"Falta R","OK")) -> OK
A10: Dato maestro | B10: 1.1 | C10: Datos de planificación del material | G10: I | I10: A/R | J10: I | L10: C | P10: C | S10: =IF(COUNTIF(D10:R10,"A")+COUNTIF(D10:R10,"A/R")<>1,"Revisar A",IF(COUNTIF(D10:R10,"R")+COUNTIF(D10:R10,"A/R")=0,"Falta R","OK")) -> OK
A11: Dato maestro | B11: 1.2 | C11: Segmentación ABC/XYZ y estrategia MTS/MTO | E11: A | F11: C | I11: R | J11: C | K11: I | P11: I | Q11: C | S11: =IF(COUNTIF(D11:R11,"A")+COUNTIF(D11:R11,"A/R")<>1,"Revisar A",IF(COUNTIF(D11:R11,"R")+COUNTIF(D11:R11,"A/R")=0,"Falta R","OK")) -> OK
A12: Dato maestro | B12: 1.3 | C12: Velocidades, tiempos de cambio y rutas | I12: A/R | J12: I | L12: R | N12: C | S12: =IF(COUNTIF(D12:R12,"A")+COUNTIF(D12:R12,"A/R")<>1,"Revisar A",IF(COUNTIF(D12:R12,"R")+COUNTIF(D12:R12,"A/R")=0,"Falta R","OK")) -> OK
A13: Dato maestro | B13: 1.4 | C13: Calendario de turnos, días y paradas | I13: I | J13: A | K13: I | L13: R | N13: C | S13: =IF(COUNTIF(D13:R13,"A")+COUNTIF(D13:R13,"A/R")<>1,"Revisar A",IF(COUNTIF(D13:R13,"R")+COUNTIF(D13:R13,"A/R")=0,"Falta R","OK")) -> OK
A14: Dato maestro | B14: 1.5 | C14: Auditoría de calidad del dato | D14: I | E14: A | I14: R | J14: C | S14: =IF(COUNTIF(D14:R14,"A")+COUNTIF(D14:R14,"A/R")<>1,"Revisar A",IF(COUNTIF(D14:R14,"R")+COUNTIF(D14:R14,"A/R")=0,"Falta R","OK")) -> OK
A15: Demanda | B15: 2.1 | C15: Previsión de demanda | F15: C | J15: A | K15: R | L15: I | P15: I | Q15: C | S15: =IF(COUNTIF(D15:R15,"A")+COUNTIF(D15:R15,"A/R")<>1,"Revisar A",IF(COUNTIF(D15:R15,"R")+COUNTIF(D15:R15,"A/R")=0,"Falta R","OK")) -> OK
A16: Demanda | B16: 2.2 | C16: Consenso de la previsión con Comercial | D16: I | F16: A | J16: C | K16: R | Q16: C | S16: =IF(COUNTIF(D16:R16,"A")+COUNTIF(D16:R16,"A/R")<>1,"Revisar A",IF(COUNTIF(D16:R16,"R")+COUNTIF(D16:R16,"A/R")=0,"Falta R","OK")) -> OK
A17: Demanda | B17: 2.3 | C17: Demanda perdida (agotados) | F17: I | J17: A | K17: R | Q17: C | S17: =IF(COUNTIF(D17:R17,"A")+COUNTIF(D17:R17,"A/R")<>1,"Revisar A",IF(COUNTIF(D17:R17,"R")+COUNTIF(D17:R17,"A/R")=0,"Falta R","OK")) -> OK
A18: Demanda | B18: 2.4 | C18: Precisión y sesgo de la previsión | D18: I | F18: A | J18: C | K18: R | Q18: C | S18: =IF(COUNTIF(D18:R18,"A")+COUNTIF(D18:R18,"A/R")<>1,"Revisar A",IF(COUNTIF(D18:R18,"R")+COUNTIF(D18:R18,"A/R")=0,"Falta R","OK")) -> OK
A19: Cartera | B19: 3.1 | C19: Revisión diaria de la cartera | J19: A | K19: R | L19: I | Q19: C | S19: =IF(COUNTIF(D19:R19,"A")+COUNTIF(D19:R19,"A/R")<>1,"Revisar A",IF(COUNTIF(D19:R19,"R")+COUNTIF(D19:R19,"A/R")=0,"Falta R","OK")) -> OK
A20: Cartera | B20: 3.2 | C20: Cargas vinculadas a pedidos | J20: A | K20: C | Q20: I | R20: R | S20: =IF(COUNTIF(D20:R20,"A")+COUNTIF(D20:R20,"A/R")<>1,"Revisar A",IF(COUNTIF(D20:R20,"R")+COUNTIF(D20:R20,"A/R")=0,"Falta R","OK")) -> OK
A21: Cartera | B21: 3.3 | C21: Cierre (saldado) de pedidos | J21: A | K21: R | Q21: C | R21: I | S21: =IF(COUNTIF(D21:R21,"A")+COUNTIF(D21:R21,"A/R")<>1,"Revisar A",IF(COUNTIF(D21:R21,"R")+COUNTIF(D21:R21,"A/R")=0,"Falta R","OK")) -> OK
A22: Cartera | B22: 3.4 | C22: Prioridad de pedidos en conflicto | F22: C | H22: I | J22: A | K22: R | L22: C | Q22: C | S22: =IF(COUNTIF(D22:R22,"A")+COUNTIF(D22:R22,"A/R")<>1,"Revisar A",IF(COUNTIF(D22:R22,"R")+COUNTIF(D22:R22,"A/R")=0,"Falta R","OK")) -> OK
A23: Necesidades | B23: 4.1 | C23: Ejecución y revisión del MRP | I23: C | J23: A | L23: I | O23: I | P23: R | S23: =IF(COUNTIF(D23:R23,"A")+COUNTIF(D23:R23,"A/R")<>1,"Revisar A",IF(COUNTIF(D23:R23,"R")+COUNTIF(D23:R23,"A/R")=0,"Falta R","OK")) -> OK
A24: Necesidades | B24: 4.2 | C24: Propuesta de fabricación de producto terminado | J24: A | K24: R | L24: C | P24: C | Q24: I | S24: =IF(COUNTIF(D24:R24,"A")+COUNTIF(D24:R24,"A/R")<>1,"Revisar A",IF(COUNTIF(D24:R24,"R")+COUNTIF(D24:R24,"A/R")=0,"Falta R","OK")) -> OK
A25: Necesidades | B25: 4.3 | C25: Necesidades de semielaborado | J25: A | L25: C | N25: I | P25: R | S25: =IF(COUNTIF(D25:R25,"A")+COUNTIF(D25:R25,"A/R")<>1,"Revisar A",IF(COUNTIF(D25:R25,"R")+COUNTIF(D25:R25,"A/R")=0,"Falta R","OK")) -> OK
A26: Necesidades | B26: 4.4 | C26: Necesidades de materias primas y auxiliares | F26: I | J26: A | O26: C | P26: R | S26: =IF(COUNTIF(D26:R26,"A")+COUNTIF(D26:R26,"A/R")<>1,"Revisar A",IF(COUNTIF(D26:R26,"R")+COUNTIF(D26:R26,"A/R")=0,"Falta R","OK")) -> OK
A27: Capacidad | B27: 5.1 | C27: Carga de capacidad y saturación por línea | F27: I | H27: I | J27: A | L27: R | N27: C | S27: =IF(COUNTIF(D27:R27,"A")+COUNTIF(D27:R27,"A/R")<>1,"Revisar A",IF(COUNTIF(D27:R27,"R")+COUNTIF(D27:R27,"A/R")=0,"Falta R","OK")) -> OK
A28: Capacidad | B28: 5.2 | C28: Balanceo entre líneas y plantas | D28: I | F28: A | H28: C | J28: R | L28: C | Q28: I | S28: =IF(COUNTIF(D28:R28,"A")+COUNTIF(D28:R28,"A/R")<>1,"Revisar A",IF(COUNTIF(D28:R28,"R")+COUNTIF(D28:R28,"A/R")=0,"Falta R","OK")) -> OK
A29: Capacidad | B29: 5.3 | C29: Saturación de almacenes | J29: A | L29: R | N29: I | R29: C | S29: =IF(COUNTIF(D29:R29,"A")+COUNTIF(D29:R29,"A/R")<>1,"Revisar A",IF(COUNTIF(D29:R29,"R")+COUNTIF(D29:R29,"A/R")=0,"Falta R","OK")) -> OK
A30: Programación | B30: 6.1 | C30: Plan de producción semanal | H30: I | J30: A | K30: C | L30: R | N30: C | P30: C | Q30: I | S30: =IF(COUNTIF(D30:R30,"A")+COUNTIF(D30:R30,"A/R")<>1,"Revisar A",IF(COUNTIF(D30:R30,"R")+COUNTIF(D30:R30,"A/R")=0,"Falta R","OK")) -> OK
A31: Programación | B31: 6.2 | C31: Secuenciación, ciclos y combinación | J31: A | K31: I | L31: R | N31: C | S31: =IF(COUNTIF(D31:R31,"A")+COUNTIF(D31:R31,"A/R")<>1,"Revisar A",IF(COUNTIF(D31:R31,"R")+COUNTIF(D31:R31,"A/R")=0,"Falta R","OK")) -> OK
A32: Programación | B32: 6.3 | C32: Lanzamiento de órdenes a máquina | J32: A | K32: C | L32: R | N32: I | S32: =IF(COUNTIF(D32:R32,"A")+COUNTIF(D32:R32,"A/R")<>1,"Revisar A",IF(COUNTIF(D32:R32,"R")+COUNTIF(D32:R32,"A/R")=0,"Falta R","OK")) -> OK
A33: Programación | B33: 6.4 | C33: Replanificación ante incidencias | J33: A | K33: C | L33: R | N33: C | Q33: I | S33: =IF(COUNTIF(D33:R33,"A")+COUNTIF(D33:R33,"A/R")<>1,"Revisar A",IF(COUNTIF(D33:R33,"R")+COUNTIF(D33:R33,"A/R")=0,"Falta R","OK")) -> OK
A34: Programación | B34: 6.5 | C34: Cronograma de cambios | J34: A | L34: R | N34: C | S34: =IF(COUNTIF(D34:R34,"A")+COUNTIF(D34:R34,"A/R")<>1,"Revisar A",IF(COUNTIF(D34:R34,"R")+COUNTIF(D34:R34,"A/R")=0,"Falta R","OK")) -> OK
A35: Entrega | B35: 7.1 | C35: Compromiso de fecha al cliente | J35: A | K35: R | L35: C | Q35: I | S35: =IF(COUNTIF(D35:R35,"A")+COUNTIF(D35:R35,"A/R")<>1,"Revisar A",IF(COUNTIF(D35:R35,"R")+COUNTIF(D35:R35,"A/R")=0,"Falta R","OK")) -> OK
A36: Entrega | B36: 7.2 | C36: Reserva de stock a pedidos | J36: A | K36: R | Q36: I | R36: C | S36: =IF(COUNTIF(D36:R36,"A")+COUNTIF(D36:R36,"A/R")<>1,"Revisar A",IF(COUNTIF(D36:R36,"R")+COUNTIF(D36:R36,"A/R")=0,"Falta R","OK")) -> OK
A37: Entrega | B37: 7.3 | C37: Retrasos y aviso al cliente | H37: I | J37: A | K37: R | L37: C | Q37: R | S37: =IF(COUNTIF(D37:R37,"A")+COUNTIF(D37:R37,"A/R")<>1,"Revisar A",IF(COUNTIF(D37:R37,"R")+COUNTIF(D37:R37,"A/R")=0,"Falta R","OK")) -> OK
A38: Entrega | B38: 7.4 | C38: Coordinación con expediciones | J38: A | K38: R | Q38: I | R38: R | S38: =IF(COUNTIF(D38:R38,"A")+COUNTIF(D38:R38,"A/R")<>1,"Revisar A",IF(COUNTIF(D38:R38,"R")+COUNTIF(D38:R38,"A/R")=0,"Falta R","OK")) -> OK
A39: Control | B39: 8.1 | C39: Plan frente a real (adherencia) | E39: I | H39: I | J39: A | L39: R | N39: C | S39: =IF(COUNTIF(D39:R39,"A")+COUNTIF(D39:R39,"A/R")<>1,"Revisar A",IF(COUNTIF(D39:R39,"R")+COUNTIF(D39:R39,"A/R")=0,"Falta R","OK")) -> OK
A40: Control | B40: 8.2 | C40: OEE y rendimiento por máquina | E40: I | H40: A | J40: I | L40: C | N40: R | S40: =IF(COUNTIF(D40:R40,"A")+COUNTIF(D40:R40,"A/R")<>1,"Revisar A",IF(COUNTIF(D40:R40,"R")+COUNTIF(D40:R40,"A/R")=0,"Falta R","OK")) -> OK
...

Sheet RACI as-is
A1: RACI as-is · cómo se hace hoy en cada empresa
A3: Empresa | B3: Proceso | C3: ID | D3: Actividad | E3: Dir. Planificación | F3: Resp. procesos | G3: S&OP / Intercompany | H3: Sistemas | I3: Dir. planta | J3: Dato maestro | K3: Resp. planif. planta | L3: Demanda y cartera | M3: Programación | N3: Producción | O3: Producción | P3: Compras | Q3: Materiales | R3: Comercial | S3: Logística | T3: Revisión | U3: Dif. con to-be
A4: Ondupet | B4: Dato maestro | C4: 1.1 | D4: Datos de planificación del material | J4: A/R | K4: C | R4: C | T4: =IF(COUNTIF(E4:S4,"A")+COUNTIF(E4:S4,"A/R")<>1,"Revisar A",IF(COUNTIF(E4:S4,"R")+COUNTIF(E4:S4,"A/R")=0,"Falta R","OK")) -> OK | U4: =SUMPRODUCT(--(E4:S4<>RACI!D10:R10)) -> 5
A5: Ondupet | B5: Dato maestro | C5: 1.3 | D5: Velocidades, tiempos de cambio y rutas | J5: A/R | T5: =IF(COUNTIF(E5:S5,"A")+COUNTIF(E5:S5,"A/R")<>1,"Revisar A",IF(COUNTIF(E5:S5,"R")+COUNTIF(E5:S5,"A/R")=0,"Falta R","OK")) -> OK | U5: =SUMPRODUCT(--(E5:S5<>RACI!D12:R12)) -> 3
A6: Ondupet | B6: Dato maestro | C6: 1.5 | D6: Auditoría de calidad del dato | J6: R | T6: =IF(COUNTIF(E6:S6,"A")+COUNTIF(E6:S6,"A/R")<>1,"Revisar A",IF(COUNTIF(E6:S6,"R")+COUNTIF(E6:S6,"A/R")=0,"Falta R","OK")) -> Revisar A | U6: =SUMPRODUCT(--(E6:S6<>RACI!D14:R14)) -> 3
A7: Ondupet | B7: Demanda | C7: 2.1 | D7: Previsión de demanda | L7: I | R7: A/R | T7: =IF(COUNTIF(E7:S7,"A")+COUNTIF(E7:S7,"A/R")<>1,"Revisar A",IF(COUNTIF(E7:S7,"R")+COUNTIF(E7:S7,"A/R")=0,"Falta R","OK")) -> OK | U7: =SUMPRODUCT(--(E7:S7<>RACI!D15:R15)) -> 6
A8: Ondupet | B8: Demanda | C8: 2.3 | D8: Demanda perdida (agotados) | R8: R | T8: =IF(COUNTIF(E8:S8,"A")+COUNTIF(E8:S8,"A/R")<>1,"Revisar A",IF(COUNTIF(E8:S8,"R")+COUNTIF(E8:S8,"A/R")=0,"Falta R","OK")) -> Revisar A | U8: =SUMPRODUCT(--(E8:S8<>RACI!D17:R17)) -> 4
A9: Ondupet | B9: Demanda | C9: 2.4 | D9: Precisión y sesgo de la previsión | L9: R | R9: R | T9: =IF(COUNTIF(E9:S9,"A")+COUNTIF(E9:S9,"A/R")<>1,"Revisar A",IF(COUNTIF(E9:S9,"R")+COUNTIF(E9:S9,"A/R")=0,"Falta R","OK")) -> Revisar A | U9: =SUMPRODUCT(--(E9:S9<>RACI!D18:R18)) -> 4
A10: Ondupet | B10: Cartera | C10: 3.1 | D10: Revisión diaria de la cartera | L10: R | N10: I | R10: A/R | T10: =IF(COUNTIF(E10:S10,"A")+COUNTIF(E10:S10,"A/R")<>1,"Revisar A",IF(COUNTIF(E10:S10,"R")+COUNTIF(E10:S10,"A/R")=0,"Falta R","OK")) -> OK | U10: =SUMPRODUCT(--(E10:S10<>RACI!D19:R19)) -> 4
A11: Ondupet | B11: Cartera | C11: 3.2 | D11: Cargas vinculadas a pedidos | L11: C | S11: A/R | T11: =IF(COUNTIF(E11:S11,"A")+COUNTIF(E11:S11,"A/R")<>1,"Revisar A",IF(COUNTIF(E11:S11,"R")+COUNTIF(E11:S11,"A/R")=0,"Falta R","OK")) -> OK | U11: =SUMPRODUCT(--(E11:S11<>RACI!D20:R20)) -> 3
A12: Ondupet | B12: Cartera | C12: 3.3 | D12: Cierre (saldado) de pedidos | R12: A/R | T12: =IF(COUNTIF(E12:S12,"A")+COUNTIF(E12:S12,"A/R")<>1,"Revisar A",IF(COUNTIF(E12:S12,"R")+COUNTIF(E12:S12,"A/R")=0,"Falta R","OK")) -> OK | U12: =SUMPRODUCT(--(E12:S12<>RACI!D21:R21)) -> 4
A13: Ondupet | B13: Cartera | C13: 3.4 | D13: Prioridad de pedidos en conflicto | I13: A | L13: R | R13: C | T13: =IF(COUNTIF(E13:S13,"A")+COUNTIF(E13:S13,"A/R")<>1,"Revisar A",IF(COUNTIF(E13:S13,"R")+COUNTIF(E13:S13,"A/R")=0,"Falta R","OK")) -> OK | U13: =SUMPRODUCT(--(E13:S13<>RACI!D22:R22)) -> 4
